<?xml version="1.0" encoding="utf-8"?>
<!-- This URDF was automatically created by SolidWorks to URDF Exporter! Originally created by Stephen Brawner (brawner@gmail.com) 
     Commit Version: 1.6.0-1-g15f4949  Build Version: 1.6.7594.29634
     For more information, please see http://wiki.ros.org/sw_urdf_exporter -->
<robot
  xmlns:xacro="http://ros.org/wiki/xacro"
  name="toilet_urdf">
  <link
    name="base_link">
    <inertial>
      <origin
        xyz="-0.0022188 -0.077174 0.28987"
        rpy="0 0 0" />
      <mass
        value="15.916" />
      <inertia
        ixx="0.62837"
        ixy="-0.001174"
        ixz="-0.00021831"
        iyy="0.41311"
        iyz="-0.047911"
        izz="0.46425" />
    </inertial>
    <visual>
      <origin
        xyz="0 0 0"
        rpy="0 0 0" />
      <geometry>
        <mesh
          filename="package://toilet_urdf/meshes/base_link.STL" />
      </geometry>
      <material
        name="">
        <color
          rgba="0.79608 0.82353 0.93725 1" />
      </material>
    </visual>
    <collision>
      <origin
        xyz="0 0 0"
        rpy="0 0 0" />
      <geometry>
        <mesh
          filename="package://toilet_urdf/meshes/base_link.STL" />
      </geometry>
    </collision>
  </link>
  <link
    name="toilet_shaft_link">
    <inertial>
      <origin
        xyz="1.6914E-17 5.5511E-17 1.7347E-18"
        rpy="0 0 0" />
      <mass
        value="0.023616" />
      <inertia
        ixx="4.2361E-07"
        ixy="-8.5674E-39"
        ixz="9.2644E-23"
        iyy="8.6036E-05"
        iyz="-1.7001E-40"
        izz="8.6036E-05" />
    </inertial>
    <visual>
      <origin
        xyz="0 0 0"
        rpy="0 0 0" />
      <geometry>
        <mesh
          filename="package://toilet_urdf/meshes/toilet_shaft_link.STL" />
      </geometry>
      <material
        name="">
        <color
          rgba="0.79608 0.82353 0.93725 1" />
      </material>
    </visual>
    <collision>
      <origin
        xyz="0 0 0"
        rpy="0 0 0" />
      <geometry>
        <mesh
          filename="package://toilet_urdf/meshes/toilet_shaft_link.STL" />
      </geometry>
    </collision>
  </link>
  <joint
    name="toiley_shaft_joint"
    type="fixed">
    <origin
      xyz="-0.003 0.0115 0.4165"
      rpy="1.5708 0 0" />
    <parent
      link="base_link" />
    <child
      link="toilet_shaft_link" />
    <axis
      xyz="0 0 0" />
  </joint>
  <link
    name="toilet_cover_link">
    <inertial>
      <origin
        xyz="0.0029453 0.22576 -0.02496"
        rpy="0 0 0" />
      <mass
        value="0.4649" />
      <inertia
        ixx="0.0076253"
        ixy="-2.4085E-06"
        ixz="1.5042E-07"
        iyy="0.0057384"
        iyz="9.3507E-05"
        izz="0.013289" />
    </inertial>
    <visual>
      <origin
        xyz="0 0 0"
        rpy="0 0 0" />
      <geometry>
        <mesh
          filename="package://toilet_urdf/meshes/toilet_cover_link.STL" />
      </geometry>
      <material
        name="">
        <color
          rgba="0.98824 0.73725 0.51765 1" />
      </material>
    </visual>
    <collision>
      <origin
        xyz="0 0 0"
        rpy="0 0 0" />
      <geometry>
        <mesh
          filename="package://toilet_urdf/meshes/toilet_cover_link.STL" />
      </geometry>
    </collision>
  </link>
  <joint
    name="toilet_cover_joint"
    type="revolute">
    <origin
      xyz="0 0 0"
      rpy="0 0 0" />
    <parent
      link="toilet_shaft_link" />
    <child
      link="toilet_cover_link" />
    <axis
      xyz="-1 0 0" />
    <limit
      lower="-1.57"
      upper="0"
      effort="1000"
      velocity="0" />
  </joint>
</robot>