<?xml version="1.0" encoding="utf-8"?>
<!-- This URDF was automatically created by SolidWorks to URDF Exporter! Originally created by Stephen Brawner (brawner@gmail.com) 
     Commit Version: 1.6.0-1-g15f4949  Build Version: 1.6.7594.29634
     For more information, please see http://wiki.ros.org/sw_urdf_exporter -->
<robot xmlns:xacro="http://www.ros.org/wiki/xacro" name="mycobot_320">
  <xacro:property name="width" value=".2"/>

  <link name="arm_base">
    <inertial>
      <origin xyz="-0.00314201374155656 -0.000316576969441296 0.0310618347596631" rpy="0 0 0" />
      <mass value="0.92353" />
      <inertia ixx="0.00084401" ixy="-7.3631E-06" ixz="1.4091E-06" iyy="0.00083129" iyz="-4.0382E-06" izz="0.0010931" />
    </inertial>
    <visual>
      <origin xyz="0 0 0" rpy="0 0 0" />
      <geometry>
        <mesh filename="package://mycobot_320/urdf/320_urdf/meshes/arm_base.STL" />
      </geometry>
      <material name="">
        <color rgba="0.752941176470588 0.752941176470588 0.752941176470588 1" />
      </material>
    </visual>
    <collision>
      <origin xyz="0 0 0" rpy="0 0 0" />
      <geometry>
        <mesh filename="package://mycobot_320/urdf/320_urdf/meshes/arm_base.STL" />
      </geometry>
    </collision>
  </link>

  <link name="j1">
    <inertial>
      <origin xyz="-4.65008859791595E-06 -0.00713845775566615 0.039058845834672" rpy="0 0 0" />
      <mass value="0.3331" />
      <inertia ixx="0.00029036" ixy="5.13E-08" ixz="-1.5737E-07" iyy="0.0002951" iyz="8.4643E-05" izz="0.00013646" />
    </inertial>
    <visual>
      <origin xyz="0 0 0" rpy="0 0 0" />
      <geometry>
        <mesh filename="package://mycobot_320/urdf/320_urdf/meshes/j1.STL" />
      </geometry>
      <material name="">
        <color rgba="0.752941176470588 0.752941176470588 0.752941176470588 1" />
      </material>
    </visual>
    <collision>
      <origin xyz="0 0 0" rpy="0 0 0" />
      <geometry>
        <mesh filename="package://mycobot_320/urdf/320_urdf/meshes/j1.STL" />
      </geometry>
    </collision>
  </link>

  <joint name="j1_to_base" type="revolute">
    <origin xyz="0 0 0.072677" rpy="0 0 1.5423" />
    <parent link="arm_base" />
    <child link="j1" />
    <axis xyz="0 0 1" />
    <limit lower="-3.14" upper="3.14159" effort="1000" velocity="0" />
  </joint>

  <link name="j2">
    <inertial>
      <origin xyz="-0.0513897959483668 1.03416109062133E-07 0.0428557705148588" rpy="0 0 0" />
      <mass value="0.29389" />
      <inertia ixx="8.6708E-05" ixy="-4.9801E-08" ixz="-1.5666E-05" iyy="0.00070218" iyz="3.0907E-08" izz="0.0007426" />
    </inertial>
    <visual>
      <origin xyz="0 0 0" rpy="0 0 0" />
      <geometry>
        <mesh filename="package://mycobot_320/urdf/320_urdf/meshes/j2.STL" />
      </geometry>
      <material name="">
        <color rgba="0.752941176470588 0.752941176470588 0.752941176470588 1" />
      </material>
    </visual>
    <collision>
      <origin xyz="0 0 0" rpy="0 0 0" />
      <geometry>
        <mesh filename="package://mycobot_320/urdf/320_urdf/meshes/j2.STL" />
      </geometry>
    </collision>
  </link>

  <joint name="j2_to_j1" type="revolute">
    <origin xyz="0 -0.0035666 0.06053" rpy="1.5708 1.5527 0" />
    <parent link="j1" />
    <child link="j2" />
    <axis xyz="0 0 1" />
    <limit lower="-3.14" upper="3.14159" effort="1000" velocity="0" />
  </joint>

  <link name="j3">
    <inertial>
      <origin xyz="-0.0437220859914132 -1.2774481847333E-06 0.00135653065468257" rpy="0 0 0" />
      <mass value="0.41605" />
      <inertia ixx="0.00010682" ixy="-3.791E-08" ixz="-3.1585E-05" iyy="0.00075981" iyz="-1.9856E-08" izz="0.0007926" />
    </inertial>
    <visual>
      <origin xyz="0 0 0" rpy="0 0 0" />
      <geometry>
        <mesh filename="package://mycobot_320/urdf/320_urdf/meshes/j3.STL" />
      </geometry>
      <material name="">
        <color rgba="0.752941176470588 0.752941176470588 0.752941176470588 1" />
      </material>
    </visual>
    <collision>
      <origin xyz="0 0 0" rpy="0 0 0" />
      <geometry>
        <mesh filename="package://mycobot_320/urdf/320_urdf/meshes/j3.STL" />
      </geometry>
    </collision>
  </link>

  <joint name="j3_to_j2" type="revolute">
    <origin xyz="-0.1102 0 0" rpy="0 0 -0.43585" />
    <parent link="j2" />
    <child link="j3" />
    <axis xyz="0 0 1" />
    <limit lower="-3.14" upper="3.14159" effort="1000" velocity="0" />
  </joint>

  <link name="j4">
    <inertial>
      <origin xyz="-1.40520224535812E-05 -0.0076816570577589 0.0230103540086662" rpy="0 0 0" />
      <mass value="0.18777" />
      <inertia ixx="7.2775E-05" ixy="-9.7964E-10" ixz="1.8973E-08" iyy="6.1005E-05" iyz="2.5828E-05" izz="6.0395E-05" />
    </inertial>
    <visual>
      <origin xyz="0 0 0" rpy="0 0 0" />
      <geometry>
        <mesh filename="package://mycobot_320/urdf/320_urdf/meshes/j4.STL" />
      </geometry>
      <material name="">
        <color rgba="0.752941176470588 0.752941176470588 0.752941176470588 1" />
      </material>
    </visual>
    <collision>
      <origin xyz="0 0 0" rpy="0 0 0" />
      <geometry>
        <mesh filename="package://mycobot_320/urdf/320_urdf/meshes/j4.STL" />
      </geometry>
    </collision>
  </link>

  <joint name="j4_to_j3" type="revolute">
    <origin xyz="-0.096 0 0.027014" rpy="0 0 0.56721" />
    <parent link="j3" />
    <child link="j4" />
    <axis xyz="0 0 1" />
    <limit lower="-3.14" upper="3.14159" effort="1000" velocity="0" />
  </joint>

  <link name="j5">
    <inertial>
      <origin xyz="0.000112529211153511 0.00287540778498707 0.0396485032237697" rpy="0 0 0" />
      <mass value="0.22519" />
      <inertia ixx="0.00010227" ixy="-2.212E-07" ixz="-8.7613E-08" iyy="0.00010156" iyz="-2.3391E-05" izz="6.5009E-05" />
    </inertial>
    <visual>
      <origin xyz="0 0 0" rpy="0 0 0" />
      <geometry>
        <mesh filename="package://mycobot_320/urdf/320_urdf/meshes/j5.STL" />
      </geometry>
      <material name="">
        <color rgba="0.752941176470588 0.752941176470588 0.752941176470588 1" />
      </material>
    </visual>
    <collision>
      <origin xyz="0 0 0" rpy="0 0 0" />
      <geometry>
        <mesh filename="package://mycobot_320/urdf/320_urdf/meshes/j5.STL" />
      </geometry>
    </collision>
  </link>

  <joint name="j5_to_j4" type="revolute">
    <origin xyz="0 -0.024124 0.033515" rpy="1.5708 -0.64832 0" />
    <parent link="j4" />
    <child link="j5" />
    <axis xyz="0 0 1" />
    <limit lower="-3.14" upper="3.14159" effort="1000" velocity="0" />
  </joint>

  <link name="j6">
    <inertial>
      <origin xyz="-1.18357394707225E-06 -3.05824490363232E-06 0.0305489098542017" rpy="0 0 0" />
      <mass value="0.060102" />
      <inertia ixx="6.5539E-06" ixy="5.8245E-13" ixz="4.1933E-10" iyy="6.5568E-06" iyz="-1.023E-09" izz="1.0571E-05" />
    </inertial>
    <visual>
      <origin xyz="0 0 0" rpy="0 0 0" />
      <geometry>
        <mesh filename="package://mycobot_320/urdf/320_urdf/meshes/j6.STL" />
      </geometry>
      <material name="">
        <color rgba="0.792156862745098 0.819607843137255 0.933333333333333 1" />
      </material>
    </visual>
    <collision>
      <origin xyz="0 0 0" rpy="0 0 0" />
      <geometry>
        <mesh filename="package://mycobot_320/urdf/320_urdf/meshes/j6.STL" />
      </geometry>
    </collision>
  </link>

  <joint name="j6_to_j5" type="revolute">
    <origin xyz="0 0.0096091 0.051625" rpy="-1.5708 0.0010726 0" />
    <parent link="j5" />
    <child link="j6" />
    <axis xyz="0 0 1" />
    <limit lower="-3.14" upper="3.14159" effort="1000" velocity="0" />
  </joint>
</robot>