<?xml version="1.0" encoding="utf-8"?>
<!-- This URDF was automatically created by SolidWorks to URDF Exporter! Originally created by Stephen Brawner (brawner@gmail.com) 
     Commit Version: 1.6.0-1-g15f4949  Build Version: 1.6.7594.29634
     For more information, please see http://wiki.ros.org/sw_urdf_exporter -->
<robot
  name="hivebot_trolley">
  <link
    name="base_link">
    <inertial>
      <origin
        xyz="0.0235732763735559 -1.16301105845676E-16 -0.0393476182287232"
        rpy="0 0 0" />
      <mass
        value="23.4644604067189" />
      <inertia
        ixx="0.443716606385079"
        ixy="1.51028178972321E-16"
        ixz="0.00342987078268199"
        iyy="0.784701467555992"
        iyz="9.75264500412178E-19"
        izz="1.20292332901758" />
    </inertial>
    <visual>
      <origin
        xyz="0 0 0"
        rpy="0 0 0" />
      <geometry>
        <mesh
          filename="package://hivebot_trolley/meshes/base_link.STL" />
      </geometry>
      <material
        name="">
        <color
          rgba="0.792156862745098 0.819607843137255 0.933333333333333 1" />
      </material>
    </visual>
    <collision>
      <origin
        xyz="0 0 0"
        rpy="0 0 0" />
      <geometry>
        <mesh
          filename="package://hivebot_trolley/meshes/base_link.STL" />
      </geometry>
    </collision>
  </link>
  <link
    name="front_wheel_mount_plate_1">
    <inertial>
      <origin
        xyz="0 0 0.00372376098180308"
        rpy="0 0 0" />
      <mass
        value="0.0327823001646924" />
      <inertia
        ixx="1.83921920866059E-05"
        ixy="3.24615009351937E-21"
        ixz="-1.54550847789467E-22"
        iyy="1.83921920866059E-05"
        iyz="1.24661932029889E-23"
        izz="3.66220350741116E-05" />
    </inertial>
    <visual>
      <origin
        xyz="0 0 0"
        rpy="0 0 0" />
      <geometry>
        <mesh
          filename="package://hivebot_trolley/meshes/front_wheel_mount_plate_1.STL" />
      </geometry>
      <material
        name="">
        <color
          rgba="0.792156862745098 0.819607843137255 0.933333333333333 1" />
      </material>
    </visual>
    <collision>
      <origin
        xyz="0 0 0"
        rpy="0 0 0" />
      <geometry>
        <mesh
          filename="package://hivebot_trolley/meshes/front_wheel_mount_plate_1.STL" />
      </geometry>
    </collision>
  </link>
  <joint
    name="front_wheel_mount_plate_1_tobase"
    type="fixed">
    <origin
      xyz="0.28 -0.205 -0.086"
      rpy="0 0 3.1416" />
    <parent
      link="base_link" />
    <child
      link="front_wheel_mount_plate_1" />
    <axis
      xyz="0 0 0" />
  </joint>
  <link
    name="front_wheel_holder_1">
    <inertial>
      <origin
        xyz="0 0.0353498305391302 5.55111512312578E-17"
        rpy="0 0 0" />
      <mass
        value="0.150983674432007" />
      <inertia
        ixx="0.00028266058025081"
        ixy="-3.21116342948743E-20"
        ixz="2.79944389067546E-19"
        iyy="0.000195595027956607"
        iyz="9.17390835065707E-20"
        izz="0.000185655183273928" />
    </inertial>
    <visual>
      <origin
        xyz="0 0 0"
        rpy="0 0 0" />
      <geometry>
        <mesh
          filename="package://hivebot_trolley/meshes/front_wheel_holder_1.STL" />
      </geometry>
      <material
        name="">
        <color
          rgba="0.792156862745098 0.819607843137255 0.933333333333333 1" />
      </material>
    </visual>
    <collision>
      <origin
        xyz="0 0 0"
        rpy="0 0 0" />
      <geometry>
        <mesh
          filename="package://hivebot_trolley/meshes/front_wheel_holder_1.STL" />
      </geometry>
    </collision>
  </link>
  <joint
    name="front_wheel_holder_1_toplate"
    type="continuous">
    <origin
      xyz="0 0 0"
      rpy="-1.5708 0 -3.1022" />
    <parent
      link="front_wheel_mount_plate_1" />
    <child
      link="front_wheel_holder_1" />
    <axis
      xyz="0 1 0" />
  </joint>
  <link
    name="front_wheel_1">
    <inertial>
      <origin
        xyz="0 0 5.55111512312578E-17"
        rpy="0 0 0" />
      <mass
        value="0.642809126832642" />
      <inertia
        ixx="0.000780813338623139"
        ixy="5.42101086242752E-20"
        ixz="-6.55230197504303E-20"
        iyy="0.00078081333862314"
        iyz="-1.84261108894285E-19"
        izz="0.00127745325926734" />
    </inertial>
    <visual>
      <origin
        xyz="0 0 0"
        rpy="0 0 0" />
      <geometry>
        <mesh
          filename="package://hivebot_trolley/meshes/front_wheel_1.STL" />
      </geometry>
      <material
        name="">
        <color
          rgba="0.792156862745098 0.819607843137255 0.933333333333333 1" />
      </material>
    </visual>
    <collision>
      <origin
        xyz="0 0 0"
        rpy="0 0 0" />
      <geometry>
        <mesh
          filename="package://hivebot_trolley/meshes/front_wheel_1.STL" />
      </geometry>
    </collision>
  </link>
  <joint
    name="front_wheel_1_toholder"
    type="continuous">
    <origin
      xyz="0 0.081 0"
      rpy="0 0 1.9085" />
    <parent
      link="front_wheel_holder_1" />
    <child
      link="front_wheel_1" />
    <axis
      xyz="0 0 1" />
  </joint>
  <link
    name="front_wheel_mount_plate_2">
    <inertial>
      <origin
        xyz="0 -2.77555756156289E-17 0.00372376098180308"
        rpy="0 0 0" />
      <mass
        value="0.0327823001646925" />
      <inertia
        ixx="1.83921920866059E-05"
        ixy="4.93527744713229E-21"
        ixz="-5.06886009705894E-23"
        iyy="1.83921920866059E-05"
        iyz="-2.42774695441036E-22"
        izz="3.66220350741116E-05" />
    </inertial>
    <visual>
      <origin
        xyz="0 0 0"
        rpy="0 0 0" />
      <geometry>
        <mesh
          filename="package://hivebot_trolley/meshes/front_wheel_mount_plate_2.STL" />
      </geometry>
      <material
        name="">
        <color
          rgba="0.792156862745098 0.819607843137255 0.933333333333333 1" />
      </material>
    </visual>
    <collision>
      <origin
        xyz="0 0 0"
        rpy="0 0 0" />
      <geometry>
        <mesh
          filename="package://hivebot_trolley/meshes/front_wheel_mount_plate_2.STL" />
      </geometry>
    </collision>
  </link>
  <joint
    name="front_wheel_mount_plate_2_tobase"
    type="fixed">
    <origin
      xyz="0.28 0.205 -0.086"
      rpy="0 0 3.1416" />
    <parent
      link="base_link" />
    <child
      link="front_wheel_mount_plate_2" />
    <axis
      xyz="0 0 0" />
  </joint>
  <link
    name="front_wheel_holder_2">
    <inertial>
      <origin
        xyz="0 0.0353498305391302 -1.38777878078145E-16"
        rpy="0 0 0" />
      <mass
        value="0.150983674432007" />
      <inertia
        ixx="0.00028266058025081"
        ixy="2.48099744005913E-20"
        ixz="-5.8699383244723E-19"
        iyy="0.000195595027956607"
        iyz="8.44021330596004E-20"
        izz="0.000185655183273928" />
    </inertial>
    <visual>
      <origin
        xyz="0 0 0"
        rpy="0 0 0" />
      <geometry>
        <mesh
          filename="package://hivebot_trolley/meshes/front_wheel_holder_2.STL" />
      </geometry>
      <material
        name="">
        <color
          rgba="0.792156862745098 0.819607843137255 0.933333333333333 1" />
      </material>
    </visual>
    <collision>
      <origin
        xyz="0 0 0"
        rpy="0 0 0" />
      <geometry>
        <mesh
          filename="package://hivebot_trolley/meshes/front_wheel_holder_2.STL" />
      </geometry>
    </collision>
  </link>
  <joint
    name="front_wheel_holder_2_toplate"
    type="continuous">
    <origin
      xyz="0 0 0"
      rpy="-1.5708 0 0.07963" />
    <parent
      link="front_wheel_mount_plate_2" />
    <child
      link="front_wheel_holder_2" />
    <axis
      xyz="0 1 0" />
  </joint>
  <link
    name="front_wheel_2">
    <inertial>
      <origin
        xyz="0 0 2.77555756156289E-17"
        rpy="0 0 0" />
      <mass
        value="0.642809126832642" />
      <inertia
        ixx="0.000780813338623139"
        ixy="-5.42101086242752E-20"
        ixz="4.90097043911794E-19"
        iyy="0.000780813338623139"
        iyz="-4.72387687152462E-19"
        izz="0.00127745325926734" />
    </inertial>
    <visual>
      <origin
        xyz="0 0 0"
        rpy="0 0 0" />
      <geometry>
        <mesh
          filename="package://hivebot_trolley/meshes/front_wheel_2.STL" />
      </geometry>
      <material
        name="">
        <color
          rgba="0.792156862745098 0.819607843137255 0.933333333333333 1" />
      </material>
    </visual>
    <collision>
      <origin
        xyz="0 0 0"
        rpy="0 0 0" />
      <geometry>
        <mesh
          filename="package://hivebot_trolley/meshes/front_wheel_2.STL" />
      </geometry>
    </collision>
  </link>
  <joint
    name="front_wheel_2_toholder"
    type="continuous">
    <origin
      xyz="0 0.081 0"
      rpy="0 0 2.2113" />
    <parent
      link="front_wheel_holder_2" />
    <child
      link="front_wheel_2" />
    <axis
      xyz="0 0 1" />
  </joint>
  <link
    name="back_wheel_holder_2">
    <inertial>
      <origin
        xyz="2.77555756156289E-17 2.77555756156289E-17 0.12370581952403"
        rpy="0 0 0" />
      <mass
        value="1.36689710972196" />
      <inertia
        ixx="0.00338021767437179"
        ixy="2.06305140072641E-19"
        ixz="-2.77319256608588E-19"
        iyy="0.00382021767437179"
        iyz="-1.2413112864934E-19"
        izz="0.00249215534678811" />
    </inertial>
    <visual>
      <origin
        xyz="0 0 0"
        rpy="0 0 0" />
      <geometry>
        <mesh
          filename="package://hivebot_trolley/meshes/back_wheel_holder_2.STL" />
      </geometry>
      <material
        name="">
        <color
          rgba="0.792156862745098 0.819607843137255 0.933333333333333 1" />
      </material>
    </visual>
    <collision>
      <origin
        xyz="0 0 0"
        rpy="0 0 0" />
      <geometry>
        <mesh
          filename="package://hivebot_trolley/meshes/back_wheel_holder_2.STL" />
      </geometry>
    </collision>
  </link>
  <joint
    name="back_wheel_holder_2_tobase"
    type="fixed">
    <origin
      xyz="-0.2185 -0.25 -0.13"
      rpy="1.5708 0 3.1416" />
    <parent
      link="base_link" />
    <child
      link="back_wheel_holder_2" />
    <axis
      xyz="0 0 0" />
  </joint>
  <link
    name="back_wheel_2">
    <inertial>
      <origin
        xyz="4.16333634234434E-16 -5.55111512312578E-17 0.0399999999999996"
        rpy="0 0 0" />
      <mass
        value="2.69353870933482" />
      <inertia
        ixx="0.00949511675813368"
        ixy="5.29395592033938E-23"
        ixz="9.95024472665243E-19"
        iyy="0.00949511675813367"
        iyz="-1.1541177720628E-18"
        izz="0.0161171255596435" />
    </inertial>
    <visual>
      <origin
        xyz="0 0 0"
        rpy="0 0 0" />
      <geometry>
        <mesh
          filename="package://hivebot_trolley/meshes/back_wheel_2.STL" />
      </geometry>
      <material
        name="">
        <color
          rgba="0.792156862745098 0.819607843137255 0.933333333333333 1" />
      </material>
    </visual>
    <collision>
      <origin
        xyz="0 0 0"
        rpy="0 0 0" />
      <geometry>
        <mesh
          filename="package://hivebot_trolley/meshes/back_wheel_2.STL" />
      </geometry>
    </collision>
  </link>
  <joint
    name="back_wheel_2_toholder"
    type="continuous">
    <origin
      xyz="0 0 0"
      rpy="0 0 1.5708" />
    <parent
      link="back_wheel_holder_2" />
    <child
      link="back_wheel_2" />
    <axis
      xyz="0 0 1" />
  </joint>
  <link
    name="back_wheel_holder_1">
    <inertial>
      <origin
        xyz="0 0 0.12370581952403"
        rpy="0 0 0" />
      <mass
        value="1.36689710972196" />
      <inertia
        ixx="0.00338021767437178"
        ixy="3.21237840152391E-19"
        ixz="-1.88824243478581E-19"
        iyy="0.00382021767437178"
        iyz="-1.63935584020256E-21"
        izz="0.00249215534678811" />
    </inertial>
    <visual>
      <origin
        xyz="0 0 0"
        rpy="0 0 0" />
      <geometry>
        <mesh
          filename="package://hivebot_trolley/meshes/back_wheel_holder_1.STL" />
      </geometry>
      <material
        name="">
        <color
          rgba="0.792156862745098 0.819607843137255 0.933333333333333 1" />
      </material>
    </visual>
    <collision>
      <origin
        xyz="0 0 0"
        rpy="0 0 0" />
      <geometry>
        <mesh
          filename="package://hivebot_trolley/meshes/back_wheel_holder_1.STL" />
      </geometry>
    </collision>
  </link>
  <joint
    name="back_wheel_holder_1_tobase"
    type="fixed">
    <origin
      xyz="-0.2185 0.25 -0.13"
      rpy="-1.5708 0 3.1416" />
    <parent
      link="base_link" />
    <child
      link="back_wheel_holder_1" />
    <axis
      xyz="0 0 0" />
  </joint>
  <link
    name="back_wheel_1">
    <inertial>
      <origin
        xyz="-5.55111512312578E-17 0 0.04"
        rpy="0 0 0" />
      <mass
        value="2.69353870933482" />
      <inertia
        ixx="0.00949511675813368"
        ixy="0"
        ixz="1.26731753157619E-18"
        iyy="0.00949511675813368"
        iyz="-1.52133972476596E-18"
        izz="0.0161171255596436" />
    </inertial>
    <visual>
      <origin
        xyz="0 0 0"
        rpy="0 0 0" />
      <geometry>
        <mesh
          filename="package://hivebot_trolley/meshes/back_wheel_1.STL" />
      </geometry>
      <material
        name="">
        <color
          rgba="0.792156862745098 0.819607843137255 0.933333333333333 1" />
      </material>
    </visual>
    <collision>
      <origin
        xyz="0 0 0"
        rpy="0 0 0" />
      <geometry>
        <mesh
          filename="package://hivebot_trolley/meshes/back_wheel_1.STL" />
      </geometry>
    </collision>
  </link>
  <joint
    name="back_wheel_1_toholder"
    type="continuous">
    <origin
      xyz="0 0 0"
      rpy="0 0 2.8824" />
    <parent
      link="back_wheel_holder_1" />
    <child
      link="back_wheel_1" />
    <axis
      xyz="0 0 1" />
  </joint>
  <link
    name="guiding_frame-2">
    <inertial>
      <origin
        xyz="1.40422097108178E-16 -5.55111512312578E-17 0.52082343378767"
        rpy="0 0 0" />
      <mass
        value="5.75784" />
      <inertia
        ixx="0.369158792655726"
        ixy="2.49402192883461E-18"
        ixz="5.73478237026073E-17"
        iyy="0.387658995375726"
        iyz="3.63659399409593E-17"
        izz="0.02826234816" />
    </inertial>
    <visual>
      <origin
        xyz="0 0 0"
        rpy="0 0 0" />
      <geometry>
        <mesh
          filename="package://hivebot_trolley/meshes/guiding_frame-2.STL" />
      </geometry>
      <material
        name="">
        <color
          rgba="0.792156862745098 0.819607843137255 0.933333333333333 1" />
      </material>
    </visual>
    <collision>
      <origin
        xyz="0 0 0"
        rpy="0 0 0" />
      <geometry>
        <mesh
          filename="package://hivebot_trolley/meshes/guiding_frame-2.STL" />
      </geometry>
    </collision>
  </link>
  <joint
    name="guiding-frame-2-tobase"
    type="fixed">
    <origin
      xyz="0.275 0 0.81"
      rpy="3.1416 0 -1.5708" />
    <parent
      link="base_link" />
    <child
      link="guiding_frame-2" />
    <axis
      xyz="0 0 0" />
  </joint>
  <link
    name="mount-box">
    <inertial>
      <origin
        xyz="-0.0400000000000001 -0.0599999999999999 -0.06"
        rpy="0 0 0" />
      <mass
        value="1.43838725877128" />
      <inertia
        ixx="0.00345361373947357"
        ixy="1.45609786108984E-19"
        ixz="-1.2659665150112E-19"
        iyy="0.00290597229871286"
        iyz="-6.51769155242515E-19"
        izz="0.00290766425871286" />
    </inertial>
    <visual>
      <origin
        xyz="0 0 0"
        rpy="0 0 0" />
      <geometry>
        <mesh
          filename="package://hivebot_trolley/meshes/mount-box.STL" />
      </geometry>
      <material
        name="">
        <color
          rgba="0.792156862745098 0.819607843137255 0.933333333333333 1" />
      </material>
    </visual>
    <collision>
      <origin
        xyz="0 0 0"
        rpy="0 0 0" />
      <geometry>
        <mesh
          filename="package://hivebot_trolley/meshes/mount-box.STL" />
      </geometry>
    </collision>
  </link>
  <joint
    name="mount-box-to-frame"
    type="prismatic">
    <origin
      xyz="0.06 -0.04 0.11989"
      rpy="-1.5708 0 -1.5708" />
    <parent
      link="guiding_frame-2" />
    <child
      link="mount-box" />
    <axis
      xyz="0 1 0" />
    <limit
      lower="-0.38"
      upper="0.1"
      effort="0"
      velocity="0" />
  </joint>
  <link
    name="surrounding-frame">
    <inertial>
      <origin
        xyz="0.25081880830438 -0.0984828202328318 0.385306866228244"
        rpy="0 0 0" />
      <mass
        value="39.1078118021391" />
      <inertia
        ixx="1.55288148334587"
        ixy="-0.00153801040030465"
        ixz="0.00220493109382033"
        iyy="1.67301946819098"
        iyz="0.0166316312278493"
        izz="1.1231420016058" />
    </inertial>
    <visual>
      <origin
        xyz="0 0 0"
        rpy="0 0 0" />
      <geometry>
        <mesh
          filename="package://hivebot_trolley/meshes/surrounding-frame.STL" />
      </geometry>
      <material
        name="">
        <color
          rgba="0.792156862745098 0.819607843137255 0.933333333333333 1" />
      </material>
    </visual>
    <collision>
      <origin
        xyz="0 0 0"
        rpy="0 0 0" />
      <geometry>
        <mesh
          filename="package://hivebot_trolley/meshes/surrounding-frame.STL" />
      </geometry>
    </collision>
  </link>
  <joint
    name="surrounding-frame-to-base"
    type="fixed">
    <origin
      xyz="0.225 -0.25 0.81"
      rpy="3.1416 0 1.5708" />
    <parent
      link="base_link" />
    <child
      link="surrounding-frame" />
    <axis
      xyz="0 0 0" />
  </joint>
  <link
    name="cover-door">
    <inertial>
      <origin
        xyz="0.137890062430959 0.150040997767576 -0.000110355172872834"
        rpy="0 0 0" />
      <mass
        value="1.71577433388231" />
      <inertia
        ixx="0.0128235955145912"
        ixy="-7.18271089932621E-06"
        ixz="1.93339625511969E-05"
        iyy="0.0117484833677518"
        iyz="1.88568302746812E-06"
        izz="0.0244481959322745" />
    </inertial>
    <visual>
      <origin
        xyz="0 0 0"
        rpy="0 0 0" />
      <geometry>
        <mesh
          filename="package://hivebot_trolley/meshes/cover-door.STL" />
      </geometry>
      <material
        name="">
        <color
          rgba="0.792156862745098 0.819607843137255 0.933333333333333 1" />
      </material>
    </visual>
    <collision>
      <origin
        xyz="0 0 0"
        rpy="0 0 0" />
      <geometry>
        <mesh
          filename="package://hivebot_trolley/meshes/cover-door.STL" />
      </geometry>
    </collision>
  </link>
  <joint
    name="cover-door-to-frame"
    type="continuous">
    <origin
      xyz="0.36855 -0.06 0.01"
      rpy="0 0.001715 3.1416" />
    <parent
      link="surrounding-frame" />
    <child
      link="cover-door" />
    <axis
      xyz="0 1 0" />
  </joint>
  <link
    name="tablet">
    <inertial>
      <origin
        xyz="1.36883635898117E-05 0.00296570177312283 4.00530110057362E-05"
        rpy="0 0 0" />
      <mass
        value="0.113687986940389" />
      <inertia
        ixx="0.000111445471191984"
        ixy="-6.15789915572864E-11"
        ixz="2.32192465433345E-08"
        iyy="0.000413028900787828"
        iyz="2.72645884829236E-08"
        izz="0.000302229544189519" />
    </inertial>
    <visual>
      <origin
        xyz="0 0 0"
        rpy="0 0 0" />
      <geometry>
        <mesh
          filename="package://hivebot_trolley/meshes/tablet.STL" />
      </geometry>
      <material
        name="">
        <color
          rgba="0.792156862745098 0.819607843137255 0.933333333333333 1" />
      </material>
    </visual>
    <collision>
      <origin
        xyz="0 0 0"
        rpy="0 0 0" />
      <geometry>
        <mesh
          filename="package://hivebot_trolley/meshes/tablet.STL" />
      </geometry>
    </collision>
  </link>
  <joint
    name="tablet-to-frame"
    type="fixed">
    <origin
      xyz="0.251 -0.47364 0.070711"
      rpy="-0.7854 0 -3.1416" />
    <parent
      link="surrounding-frame" />
    <child
      link="tablet" />
    <axis
      xyz="0 0 0" />
  </joint>
  <link
    name="handle">
    <inertial>
      <origin
        xyz="0.2 0 0.0683128872678796"
        rpy="0 0 0" />
      <mass
        value="0.383705226392601" />
      <inertia
        ixx="0.000225586911534695"
        ixy="2.06897283647009E-19"
        ixz="1.39338231937946E-18"
        iyy="0.00803378140369941"
        iyz="1.95575888623689E-20"
        izz="0.00785136133013388" />
    </inertial>
    <visual>
      <origin
        xyz="0 0 0"
        rpy="0 0 0" />
      <geometry>
        <mesh
          filename="package://hivebot_trolley/meshes/handle.STL" />
      </geometry>
      <material
        name="">
        <color
          rgba="0.792156862745098 0.819607843137255 0.933333333333333 1" />
      </material>
    </visual>
    <collision>
      <origin
        xyz="0 0 0"
        rpy="0 0 0" />
      <geometry>
        <mesh
          filename="package://hivebot_trolley/meshes/handle.STL" />
      </geometry>
    </collision>
  </link>
  <joint
    name="handle-to-frame"
    type="fixed">
    <origin
      xyz="0.05 -0.55 0.18"
      rpy="1.5708 0 0" />
    <parent
      link="surrounding-frame" />
    <child
      link="handle" />
    <axis
      xyz="0 0 0" />
  </joint>
  <link
    name="tools">
    <inertial>
      <origin
        xyz="0.192936151051069 0.120280603660325 -0.0161951081872489"
        rpy="0 0 0" />
      <mass
        value="0.532371246582646" />
      <inertia
        ixx="0.00119708517877981"
        ixy="-1.65474125270207E-05"
        ixz="-5.00577809600436E-06"
        iyy="0.00122007986339354"
        iyz="9.57355060860906E-06"
        izz="0.000526564685247578" />
    </inertial>
    <visual>
      <origin
        xyz="0 0 0"
        rpy="0 0 0" />
      <geometry>
        <mesh
          filename="package://hivebot_trolley/meshes/tools.STL" />
      </geometry>
      <material
        name="">
        <color
          rgba="0.792156862745098 0.819607843137255 0.933333333333333 1" />
      </material>
    </visual>
    <collision>
      <origin
        xyz="0 0 0"
        rpy="0 0 0" />
      <geometry>
        <mesh
          filename="package://hivebot_trolley/meshes/tools.STL" />
      </geometry>
    </collision>
  </link>
  <joint
    name="tools-to-frame"
    type="fixed">
    <origin
      xyz="0.47671 0.09305 0.59"
      rpy="3.1416 0 -2.6598" />
    <parent
      link="surrounding-frame" />
    <child
      link="tools" />
    <axis
      xyz="0 0 0" />
  </joint>
  <link
    name="compartment-1">
    <inertial>
      <origin
        xyz="-0.000407919789025102 0.0298582952007898 0.273367873191963"
        rpy="0 0 0" />
      <mass
        value="5.66237181704939" />
      <inertia
        ixx="0.211234924589257"
        ixy="6.76868449226748E-17"
        ixz="1.33025596361753E-18"
        iyy="0.230542686133498"
        iyz="-0.00553942271601607"
        izz="0.0904301793877136" />
    </inertial>
    <visual>
      <origin
        xyz="0 0 0"
        rpy="0 0 0" />
      <geometry>
        <mesh
          filename="package://hivebot_trolley/meshes/compartment-1.STL" />
      </geometry>
      <material
        name="">
        <color
          rgba="0.792156862745098 0.819607843137255 0.933333333333333 1" />
      </material>
    </visual>
    <collision>
      <origin
        xyz="0 0 0"
        rpy="0 0 0" />
      <geometry>
        <mesh
          filename="package://hivebot_trolley/meshes/compartment-1.STL" />
      </geometry>
    </collision>
  </link>
  <joint
    name="compartment-1-tobase"
    type="fixed">
    <origin
      xyz="-0.2 0.125 0"
      rpy="0 0 3.1416" />
    <parent
      link="base_link" />
    <child
      link="compartment-1" />
    <axis
      xyz="0 0 0" />
  </joint>
  <link
    name="door-1">
    <inertial>
      <origin
        xyz="0.295291950301883 0.10382999581969 1.11022302462516E-16"
        rpy="0 0 0" />
      <mass
        value="1.31049557428756" />
      <inertia
        ixx="0.00542945303432149"
        ixy="3.97253126393702E-05"
        ixz="8.26254170266968E-20"
        iyy="0.038054773608125"
        iyz="-3.99121924746226E-18"
        izz="0.0434624308644346" />
    </inertial>
    <visual>
      <origin
        xyz="0 0 0"
        rpy="0 0 0" />
      <geometry>
        <mesh
          filename="package://hivebot_trolley/meshes/door-1.STL" />
      </geometry>
      <material
        name="">
        <color
          rgba="0.792156862745098 0.819607843137255 0.933333333333333 1" />
      </material>
    </visual>
    <collision>
      <origin
        xyz="0 0 0"
        rpy="0 0 0" />
      <geometry>
        <mesh
          filename="package://hivebot_trolley/meshes/door-1.STL" />
      </geometry>
    </collision>
  </link>
  <joint
    name="door-1-to-compartment"
    type="continuous">
    <origin
      xyz="-0.1 -0.115 0.01"
      rpy="1.568 -1.5708 0" />
    <parent
      link="compartment-1" />
    <child
      link="door-1" />
    <axis
      xyz="1 0 0" />
  </joint>
  <link
    name="compartment-2">
    <inertial>
      <origin
        xyz="0.000407919789025379 0.0298582952007898 0.273367873191963"
        rpy="0 0 0" />
      <mass
        value="5.66237181704939" />
      <inertia
        ixx="0.211234924589257"
        ixy="7.54303366478574E-17"
        ixz="2.25062829490829E-17"
        iyy="0.230542686133498"
        iyz="-0.0055394227160161"
        izz="0.0904301793877136" />
    </inertial>
    <visual>
      <origin
        xyz="0 0 0"
        rpy="0 0 0" />
      <geometry>
        <mesh
          filename="package://hivebot_trolley/meshes/compartment-2.STL" />
      </geometry>
      <material
        name="">
        <color
          rgba="0.792156862745098 0.819607843137255 0.933333333333333 1" />
      </material>
    </visual>
    <collision>
      <origin
        xyz="0 0 0"
        rpy="0 0 0" />
      <geometry>
        <mesh
          filename="package://hivebot_trolley/meshes/compartment-2.STL" />
      </geometry>
    </collision>
  </link>
  <joint
    name="compartment-2-to-base"
    type="fixed">
    <origin
      xyz="-0.2 -0.125 0"
      rpy="0 0 0" />
    <parent
      link="base_link" />
    <child
      link="compartment-2" />
    <axis
      xyz="0 0 0" />
  </joint>
  <link
    name="door-2">
    <inertial>
      <origin
        xyz="0.295291950301883 0.103829995819691 1.38777878078145E-16"
        rpy="0 0 0" />
      <mass
        value="1.31049557428757" />
      <inertia
        ixx="0.0054294530343215"
        ixy="3.97253126393726E-05"
        ixz="-4.8450284582946E-19"
        iyy="0.0380547736081251"
        iyz="1.62630325872826E-18"
        izz="0.0434624308644347" />
    </inertial>
    <visual>
      <origin
        xyz="0 0 0"
        rpy="0 0 0" />
      <geometry>
        <mesh
          filename="package://hivebot_trolley/meshes/door-2.STL" />
      </geometry>
      <material
        name="">
        <color
          rgba="0.792156862745098 0.819607843137255 0.933333333333333 1" />
      </material>
    </visual>
    <collision>
      <origin
        xyz="0 0 0"
        rpy="0 0 0" />
      <geometry>
        <mesh
          filename="package://hivebot_trolley/meshes/door-2.STL" />
      </geometry>
    </collision>
  </link>
  <joint
    name="door-2-to-compartment"
    type="continuous">
    <origin
      xyz="0.1 -0.115 0.01"
      rpy="1.5394 -1.5708 0" />
    <parent
      link="compartment-2" />
    <child
      link="door-2" />
    <axis
      xyz="1 0 0" />
  </joint>
</robot>