<?xml version="1.0" encoding="utf-8"?>
<!-- This URDF was automatically created by SolidWorks to URDF Exporter! Originally created by Stephen Brawner (brawner@gmail.com) 
     Commit Version: 1.6.0-1-g15f4949  Build Version: 1.6.7594.29634
     For more information, please see http://wiki.ros.org/sw_urdf_exporter -->
<robot
  name="hivebot_trolley" xmlns:xacro="http://www.ros.org/wiki/xacro">
  <link
    name="base_link">
    <inertial>
      <origin
        xyz="0.0235732763735559 -1.16301105845676E-16 -0.0393476182287232"
        rpy="0 0 0" />
      <mass
        value="63.354" />
      <inertia
        ixx="1.198"
        ixy="3.8905E-16"
        ixz="0.0092607"
        iyy="2.1187"
        iyz="2.6213E-18"
        izz="3.2479" />
    </inertial>
    <visual>
      <origin
        xyz="0 0 0"
        rpy="0 0 0" />
      <geometry>
        <mesh
          filename="package://hivebot_trolley/meshes/base_link.STL" />
      </geometry>
      <material
        name="">
        <color
          rgba="0.89804 0.91765 0.92941 1" />
      </material>
    </visual>
    <collision>
      <origin
        xyz="0 0 0"
        rpy="0 0 0" />
      <geometry>
        <mesh
          filename="package://hivebot_trolley/meshes/base_link.STL" />
      </geometry>
    </collision>
  </link>
  <link
    name="front_wheel_mount_plate_1">
    <inertial>
      <origin
        xyz="0 0 0.00372376098180308"
        rpy="0 0 0" />
      <mass
        value="0.088512" />
      <inertia
        ixx="4.9659E-05"
        ixy="8.7646E-21"
        ixz="-4.1729E-22"
        iyy="4.9659E-05"
        iyz="3.3659E-23"
        izz="9.8879E-05" />
    </inertial>
    <visual>
      <origin
        xyz="0 0 0"
        rpy="0 0 0" />
      <geometry>
        <mesh
          filename="package://hivebot_trolley/meshes/front_wheel_mount_plate_1.STL" />
      </geometry>
      <material
        name="">
        <color
          rgba="0.89804 0.91765 0.92941 1" />
      </material>
    </visual>
    <collision>
      <origin
        xyz="0 0 0"
        rpy="0 0 0" />
      <geometry>
        <mesh
          filename="package://hivebot_trolley/meshes/front_wheel_mount_plate_1.STL" />
      </geometry>
    </collision>
  </link>
  <joint
    name="front_wheel_mount_plate_1_tobase"
    type="fixed">
    <origin
      xyz="0.28 -0.205 -0.086"
      rpy="0 0 3.1416" />
    <parent
      link="base_link" />
    <child
      link="front_wheel_mount_plate_1" />
    <axis
      xyz="0 0 0" />
  </joint>
  <link
    name="front_wheel_holder_1">
    <inertial>
      <origin
        xyz="0 0.0353498305391302 5.55111512312578E-17"
        rpy="0 0 0" />
      <mass
        value="0.40766" />
      <inertia
        ixx="0.00076318"
        ixy="-8.8118E-20"
        ixz="7.5894E-19"
        iyy="0.00052811"
        iyz="2.369E-19"
        izz="0.00050127" />
    </inertial>
    <visual>
      <origin
        xyz="0 0 0"
        rpy="0 0 0" />
      <geometry>
        <mesh
          filename="package://hivebot_trolley/meshes/front_wheel_holder_1.STL" />
      </geometry>
      <material
        name="">
        <color
          rgba="0.89804 0.91765 0.92941 1" />
      </material>
    </visual>
    <collision>
      <origin
        xyz="0 0 0"
        rpy="0 0 0" />
      <geometry>
        <mesh
          filename="package://hivebot_trolley/meshes/front_wheel_holder_1.STL" />
      </geometry>
    </collision>
  </link>
  <joint
    name="front_wheel_holder_1_toplate"
    type="continuous">
    <origin
      xyz="0 0 0"
      rpy="-1.5708 0 -3.1022" />
    <parent
      link="front_wheel_mount_plate_1" />
    <child
      link="front_wheel_holder_1" />
    <axis
      xyz="0 1 0" />
  </joint>
  <link
    name="front_wheel_1">
    <inertial>
      <origin
        xyz="0 0 5.55111512312578E-17"
        rpy="0 0 0" />
      <mass
        value="1.7356" />
      <inertia
        ixx="0.0021082"
        ixy="3.2526E-19"
        ixz="-1.6963E-19"
        iyy="0.0021082"
        iyz="-4.6684E-19"
        izz="0.0034491" />
    </inertial>
    <visual>
      <origin
        xyz="0 0 0"
        rpy="0 0 0" />
      <geometry>
        <mesh
          filename="package://hivebot_trolley/meshes/front_wheel_1.STL" />
      </geometry>
      <material
        name="">
        <color
          rgba="0.792156862745098 0.819607843137255 0.933333333333333 1" />
      </material>
    </visual>
    <collision>
      <origin
        xyz="0 0 0"
        rpy="0 0 0" />
      <geometry>
        <mesh
          filename="package://hivebot_trolley/meshes/front_wheel_1.STL" />
      </geometry>
    </collision>
  </link>
  <joint
    name="front_wheel_1_toholder"
    type="continuous">
    <origin
      xyz="0 0.081 0"
      rpy="0 0 1.9085" />
    <parent
      link="front_wheel_holder_1" />
    <child
      link="front_wheel_1" />
    <axis
      xyz="0 0 1" />
  </joint>
  <link
    name="front_wheel_mount_plate_2">
    <inertial>
      <origin
        xyz="0 -2.77555756156289E-17 0.00372376098180308"
        rpy="0 0 0" />
      <mass
        value="0.088512" />
      <inertia
        ixx="4.9659E-05"
        ixy="1.3325E-20"
        ixz="-1.3686E-22"
        iyy="4.9659E-05"
        iyz="-6.5549E-22"
        izz="9.8879E-05" />
    </inertial>
    <visual>
      <origin
        xyz="0 0 0"
        rpy="0 0 0" />
      <geometry>
        <mesh
          filename="package://hivebot_trolley/meshes/front_wheel_mount_plate_2.STL" />
      </geometry>
      <material
        name="">
        <color
          rgba="0.792156862745098 0.819607843137255 0.933333333333333 1" />
      </material>
    </visual>
    <collision>
      <origin
        xyz="0 0 0"
        rpy="0 0 0" />
      <geometry>
        <mesh
          filename="package://hivebot_trolley/meshes/front_wheel_mount_plate_2.STL" />
      </geometry>
    </collision>
  </link>
  <joint
    name="front_wheel_mount_plate_2_tobase"
    type="fixed">
    <origin
      xyz="0.28 0.205 -0.086"
      rpy="0 0 3.1416" />
    <parent
      link="base_link" />
    <child
      link="front_wheel_mount_plate_2" />
    <axis
      xyz="0 0 0" />
  </joint>
  <link
    name="front_wheel_holder_2">
    <inertial>
      <origin
        xyz="0 0.0353498305391302 -1.38777878078145E-16"
        rpy="0 0 0" />
      <mass
        value="0.40766" />
      <inertia
        ixx="0.00076318"
        ixy="6.7699E-20"
        ixz="-1.589E-18"
        iyy="0.00052811"
        iyz="2.4104E-19"
        izz="0.00050127" />
    </inertial>
    <visual>
      <origin
        xyz="0 0 0"
        rpy="0 0 0" />
      <geometry>
        <mesh
          filename="package://hivebot_trolley/meshes/front_wheel_holder_2.STL" />
      </geometry>
      <material
        name="">
        <color
          rgba="0.792156862745098 0.819607843137255 0.933333333333333 1" />
      </material>
    </visual>
    <collision>
      <origin
        xyz="0 0 0"
        rpy="0 0 0" />
      <geometry>
        <mesh
          filename="package://hivebot_trolley/meshes/front_wheel_holder_2.STL" />
      </geometry>
    </collision>
  </link>
  <joint
    name="front_wheel_holder_2_toplate"
    type="continuous">
    <origin
      xyz="0 0 0"
      rpy="-1.5708 0 0.07963" />
    <parent
      link="front_wheel_mount_plate_2" />
    <child
      link="front_wheel_holder_2" />
    <axis
      xyz="0 1 0" />
  </joint>
  <link
    name="front_wheel_2">
    <inertial>
      <origin
        xyz="0 0 2.77555756156289E-17"
        rpy="0 0 0" />
      <mass
        value="1.7356" />
      <inertia
        ixx="0.0021082"
        ixy="-3.2526E-19"
        ixz="1.2945E-18"
        iyy="0.0021082"
        iyz="-1.3425E-18"
        izz="0.0034491" />
    </inertial>
    <visual>
      <origin
        xyz="0 0 0"
        rpy="0 0 0" />
      <geometry>
        <mesh
          filename="package://hivebot_trolley/meshes/front_wheel_2.STL" />
      </geometry>
      <material
        name="">
        <color
          rgba="0.792156862745098 0.819607843137255 0.933333333333333 1" />
      </material>
    </visual>
    <collision>
      <origin
        xyz="0 0 0"
        rpy="0 0 0" />
      <geometry>
        <mesh
          filename="package://hivebot_trolley/meshes/front_wheel_2.STL" />
      </geometry>
    </collision>
  </link>
  <joint
    name="front_wheel_2_toholder"
    type="continuous">
    <origin
      xyz="0 0.081 0"
      rpy="0 0 2.2113" />
    <parent
      link="front_wheel_holder_2" />
    <child
      link="front_wheel_2" />
    <axis
      xyz="0 0 1" />
  </joint>
  <link
    name="back_wheel_holder_2">
    <inertial>
      <origin
        xyz="2.77555756156289E-17 2.77555756156289E-17 0.12370581952403"
        rpy="0 0 0" />
      <mass
        value="3.6906" />
      <inertia
        ixx="0.0091266"
        ixy="5.5702E-19"
        ixz="-7.4876E-19"
        iyy="0.010315"
        iyz="-3.3515E-19"
        izz="0.0067288" />
    </inertial>
    <visual>
      <origin
        xyz="0 0 0"
        rpy="0 0 0" />
      <geometry>
        <mesh
          filename="package://hivebot_trolley/meshes/back_wheel_holder_2.STL" />
      </geometry>
      <material
        name="">
        <color
          rgba="0.792156862745098 0.819607843137255 0.933333333333333 1" />
      </material>
    </visual>
    <collision>
      <origin
        xyz="0 0 0"
        rpy="0 0 0" />
      <geometry>
        <mesh
          filename="package://hivebot_trolley/meshes/back_wheel_holder_2.STL" />
      </geometry>
    </collision>
  </link>
  <joint
    name="back_wheel_holder_2_tobase"
    type="fixed">
    <origin
      xyz="-0.2185 -0.25 -0.13"
      rpy="1.5708 0 3.1416" />
    <parent
      link="base_link" />
    <child
      link="back_wheel_holder_2" />
    <axis
      xyz="0 0 0" />
  </joint>
  <link
    name="back_wheel_2">
    <inertial>
      <origin
        xyz="4.16333634234434E-16 -5.55111512312578E-17 0.0399999999999996"
        rpy="0 0 0" />
      <mass
        value="7.2726" />
      <inertia
        ixx="0.025637"
        ixy="2.647E-22"
        ixz="2.6866E-18"
        iyy="0.025637"
        iyz="-3.1161E-18"
        izz="0.043516" />
    </inertial>
    <visual>
      <origin
        xyz="0 0 0"
        rpy="0 0 0" />
      <geometry>
        <mesh
          filename="package://hivebot_trolley/meshes/back_wheel_2.STL" />
      </geometry>
      <material
        name="">
        <color
          rgba="0.792156862745098 0.819607843137255 0.933333333333333 1" />
      </material>
    </visual>
    <collision>
      <origin
        xyz="0 0 0"
        rpy="0 0 0" />
      <geometry>
        <mesh
          filename="package://hivebot_trolley/meshes/back_wheel_2.STL" />
      </geometry>
    </collision>
  </link>
  <joint
    name="back_wheel_2_toholder"
    type="continuous">
    <origin
      xyz="0 0 0"
      rpy="0 0 1.5708" />
    <parent
      link="back_wheel_holder_2" />
    <child
      link="back_wheel_2" />
    <axis
      xyz="0 0 1" />
  </joint>
  <link
    name="back_wheel_holder_1">
    <inertial>
      <origin
        xyz="0 0 0.12370581952403"
        rpy="0 0 0" />
      <mass
        value="3.6906" />
      <inertia
        ixx="0.0091266"
        ixy="8.6734E-19"
        ixz="-5.0983E-19"
        iyy="0.010315"
        iyz="2.5555E-20"
        izz="0.0067288" />
    </inertial>
    <visual>
      <origin
        xyz="0 0 0"
        rpy="0 0 0" />
      <geometry>
        <mesh
          filename="package://hivebot_trolley/meshes/back_wheel_holder_1.STL" />
      </geometry>
      <material
        name="">
        <color
          rgba="0.792156862745098 0.819607843137255 0.933333333333333 1" />
      </material>
    </visual>
    <collision>
      <origin
        xyz="0 0 0"
        rpy="0 0 0" />
      <geometry>
        <mesh
          filename="package://hivebot_trolley/meshes/back_wheel_holder_1.STL" />
      </geometry>
    </collision>
  </link>
  <joint
    name="back_wheel_holder_1_tobase"
    type="fixed">
    <origin
      xyz="-0.2185 0.25 -0.13"
      rpy="-1.5708 0 3.1416" />
    <parent
      link="base_link" />
    <child
      link="back_wheel_holder_1" />
    <axis
      xyz="0 0 0" />
  </joint>
  <link
    name="back_wheel_1">
    <inertial>
      <origin
        xyz="-5.55111512312578E-17 0 0.04"
        rpy="0 0 0" />
      <mass
        value="7.2726" />
      <inertia
        ixx="0.025637"
        ixy="0"
        ixz="3.4218E-18"
        iyy="0.025637"
        iyz="-4.1076E-18"
        izz="0.043516" />
    </inertial>
    <visual>
      <origin
        xyz="0 0 0"
        rpy="0 0 0" />
      <geometry>
        <mesh
          filename="package://hivebot_trolley/meshes/back_wheel_1.STL" />
      </geometry>
      <material
        name="">
        <color
          rgba="0.792156862745098 0.819607843137255 0.933333333333333 1" />
      </material>
    </visual>
    <collision>
      <origin
        xyz="0 0 0"
        rpy="0 0 0" />
      <geometry>
        <mesh
          filename="package://hivebot_trolley/meshes/back_wheel_1.STL" />
      </geometry>
    </collision>
  </link>
  <joint
    name="back_wheel_1_toholder"
    type="continuous">
    <origin
      xyz="0 0 0"
      rpy="0 0 2.8824" />
    <parent
      link="back_wheel_holder_1" />
    <child
      link="back_wheel_1" />
    <axis
      xyz="0 0 1" />
  </joint>
  <link
    name="guiding_frame-2">
    <inertial>
      <origin
        xyz="1.40422097108178E-16 -5.55111512312578E-17 0.52082343378767"
        rpy="0 0 0" />
      <mass
        value="15.546" />
      <inertia
        ixx="0.99673"
        ixy="6.6037E-18"
        ixz="1.5535E-16"
        iyy="1.0467"
        iyz="9.6464E-17"
        izz="0.076308" />
    </inertial>
    <visual>
      <origin
        xyz="0 0 0"
        rpy="0 0 0" />
      <geometry>
        <mesh
          filename="package://hivebot_trolley/meshes/guiding_frame-2.STL" />
      </geometry>
      <material
        name="">
        <color
          rgba="0.792156862745098 0.819607843137255 0.933333333333333 1" />
      </material>
    </visual>
    <collision>
      <origin
        xyz="0 0 0"
        rpy="0 0 0" />
      <geometry>
        <mesh
          filename="package://hivebot_trolley/meshes/guiding_frame-2.STL" />
      </geometry>
    </collision>
  </link>
  <joint
    name="guiding-frame-2-tobase"
    type="fixed">
    <origin
      xyz="0.275 0 0.81"
      rpy="3.1416 0 -1.5708" />
    <parent
      link="base_link" />
    <child
      link="guiding_frame-2" />
    <axis
      xyz="0 0 0" />
  </joint>
  <link
    name="mount-box">
    <inertial>
      <origin
        xyz="-0.0400000000000001 -0.0599999999999999 -0.06"
        rpy="0 0 0" />
      <mass
        value="3.8836" />
      <inertia
        ixx="0.0093248"
        ixy="4.3129E-19"
        ixz="1.0113E-20"
        iyy="0.0078461"
        iyz="-1.9951E-18"
        izz="0.0078507" />
    </inertial>
    <visual>
      <origin
        xyz="0 0 0"
        rpy="0 0 0" />
      <geometry>
        <mesh
          filename="package://hivebot_trolley/meshes/mount-box.STL" />
      </geometry>
      <material
        name="">
        <color
          rgba="0.792156862745098 0.819607843137255 0.933333333333333 1" />
      </material>
    </visual>
    <collision>
      <origin
        xyz="0 0 0"
        rpy="0 0 0" />
      <geometry>
        <mesh
          filename="package://hivebot_trolley/meshes/mount-box.STL" />
      </geometry>
    </collision>
  </link>
  <joint
    name="mount-box-to-frame"
    type="prismatic">
    <origin
      xyz="0.06 -0.04 0.11989"
      rpy="-1.5708 0 -1.5708" />
    <parent
      link="guiding_frame-2" />
    <child
      link="mount-box" />
    <axis
      xyz="0 1 0" />
    <limit
      lower="-0.38"
      upper="0.1"
      effort="0"
      velocity="0" />
  </joint>
  <link
    name="surrounding-frame">
    <inertial>
      <origin
        xyz="0.25081880830438 -0.0984828202328318 0.385306866228244"
        rpy="0 0 0" />
      <mass
        value="82.748" />
      <inertia
        ixx="3.3922"
        ixy="-0.0022233"
        ixz="0.002369"
        iyy="3.782"
        iyz="0.020109"
        izz="1.8643" />
    </inertial>
    <visual>
      <origin
        xyz="0 0 0"
        rpy="0 0 0" />
      <geometry>
        <mesh
          filename="package://hivebot_trolley/meshes/surrounding-frame.STL" />
      </geometry>
      <material
        name="">
        <color
          rgba="0.89804 0.91765 0.92941 1" />
      </material>
    </visual>
    <collision>
      <origin
        xyz="0 0 0"
        rpy="0 0 0" />
      <geometry>
        <mesh
          filename="package://hivebot_trolley/meshes/surrounding-frame.STL" />
      </geometry>
    </collision>
  </link>
  <joint
    name="surrounding-frame-to-base"
    type="fixed">
    <origin
      xyz="0.225 -0.25 0.81"
      rpy="3.1416 0 1.5708" />
    <parent
      link="base_link" />
    <child
      link="surrounding-frame" />
    <axis
      xyz="0 0 0" />
  </joint>
  <link
    name="cover-door">
    <inertial>
      <origin
        xyz="0.137890062430959 0.150040997767576 -0.000110355172872834"
        rpy="0 0 0" />
      <mass
        value="2.0589" />
      <inertia
        ixx="0.015388"
        ixy="-8.6193E-06"
        ixz="2.3201E-05"
        iyy="0.014098"
        iyz="2.2628E-06"
        izz="0.029338" />
    </inertial>
    <visual>
      <origin
        xyz="0 0 0"
        rpy="0 0 0" />
      <geometry>
        <mesh
          filename="package://hivebot_trolley/meshes/cover-door.STL" />
      </geometry>
      <material
        name="">
        <color
          rgba="1 1 1 0.3" />
      </material>
    </visual>
    <collision>
      <origin
        xyz="0 0 0"
        rpy="0 0 0" />
      <geometry>
        <mesh
          filename="package://hivebot_trolley/meshes/cover-door.STL" />
      </geometry>
    </collision>
  </link>
  <joint
    name="cover-door-to-frame"
    type="continuous">
    <origin
      xyz="0.36855 -0.06 0.01"
      rpy="0 0.001715 3.1416" />
    <parent
      link="surrounding-frame" />
    <child
      link="cover-door" />
    <axis
      xyz="0 1 0" />
  </joint>
  <link
    name="tablet">
    <inertial>
      <origin
        xyz="1.36883635898117E-05 0.00296570177312283 4.00530110057362E-05"
        rpy="0 0 0" />
      <mass
        value="0.886766298135032" />
      <inertia
        ixx="0.000869274675297478"
        ixy="-4.8031613415315E-10"
        ixz="1.8111012303801E-07"
        iyy="0.00322162542614506"
        iyz="2.12663790167015E-07"
        izz="0.00235739044467824" />
    </inertial>
    <visual>
      <origin
        xyz="0 0 0"
        rpy="0 0 0" />
      <geometry>
        <mesh
          filename="package://hivebot_trolley/meshes/tablet.STL" />
      </geometry>
      <material
        name="">
        <color
          rgba="0.529411764705882 0.549019607843137 0.549019607843137 1" />
      </material>
    </visual>
    <collision>
      <origin
        xyz="0 0 0"
        rpy="0 0 0" />
      <geometry>
        <mesh
          filename="package://hivebot_trolley/meshes/tablet.STL" />
      </geometry>
    </collision>
  </link>
  <joint
    name="tablet-to-frame"
    type="fixed">
    <origin
      xyz="0.251 -0.47364 0.070711"
      rpy="-0.7854 0 -3.1416" />
    <parent
      link="surrounding-frame" />
    <child
      link="tablet" />
    <axis
      xyz="0 0 0" />
  </joint>
  <link
    name="handle">
    <inertial>
      <origin
        xyz="0.2 0 0.0683128872678796"
        rpy="0 0 0" />
      <mass
        value="1.03600411126002" />
      <inertia
        ixx="0.000609084661143678"
        ixy="5.58622665846924E-19"
        ixz="3.76213226232454E-18"
        iyy="0.0216912097899884"
        iyz="5.2805489928396E-20"
        izz="0.0211986755913615" />
    </inertial>
    <visual>
      <origin
        xyz="0 0 0"
        rpy="0 0 0" />
      <geometry>
        <mesh
          filename="package://hivebot_trolley/meshes/handle.STL" />
      </geometry>
      <material
        name="">
        <color
          rgba="0.898039215686275 0.917647058823529 0.929411764705882 1" />
      </material>
    </visual>
    <collision>
      <origin
        xyz="0 0 0"
        rpy="0 0 0" />
      <geometry>
        <mesh
          filename="package://hivebot_trolley/meshes/handle.STL" />
      </geometry>
    </collision>
  </link>
  <joint
    name="handle-to-frame"
    type="fixed">
    <origin
      xyz="0.05 -0.55 0.18"
      rpy="1.5708 0 0" />
    <parent
      link="surrounding-frame" />
    <child
      link="handle" />
    <axis
      xyz="0 0 0" />
  </joint>
  <link
    name="tools">
    <inertial>
      <origin
        xyz="0.192936151051069 0.120280603660325 -0.0161951081872489"
        rpy="0 0 0" />
      <mass
        value="1.10101723384343" />
      <inertia
        ixx="0.00173131347854253"
        ixy="-4.46780138229562E-05"
        ixz="-1.35156008592122E-05"
        iyy="0.00179339912699962"
        iyz="2.58485866432443E-05"
        izz="0.00133528189029824" />
    </inertial>
    <visual>
      <origin
        xyz="0 0 0"
        rpy="0 0 0" />
      <geometry>
        <mesh
          filename="package://hivebot_trolley/meshes/tools.STL" />
      </geometry>
      <material
        name="">
        <color
          rgba="0.792156862745098 0.819607843137255 0.933333333333333 1" />
      </material>
    </visual>
    <collision>
      <origin
        xyz="0 0 0"
        rpy="0 0 0" />
      <geometry>
        <mesh
          filename="package://hivebot_trolley/meshes/tools.STL" />
      </geometry>
    </collision>
  </link>
  <joint
    name="tools-to-frame"
    type="fixed">
    <origin
      xyz="0.47671 0.09305 0.59"
      rpy="3.1416 0 -2.6598" />
    <parent
      link="surrounding-frame" />
    <child
      link="tools" />
    <axis
      xyz="0 0 0" />
  </joint>
  <link
    name="compartment-1">
    <inertial>
      <origin
        xyz="-0.000407919789025102 0.0298582952007898 0.273367873191963"
        rpy="0 0 0" />
      <mass
        value="1.0574" />
      <inertia
        ixx="0.033889"
        ixy="1.0836E-17"
        ixz="2.1547E-19"
        iyy="0.036978"
        iyz="-0.00088625"
        izz="0.01448" />
    </inertial>
    <visual>
      <origin
        xyz="0 0 0"
        rpy="0 0 0" />
      <geometry>
        <mesh
          filename="package://hivebot_trolley/meshes/compartment-1.STL" />
      </geometry>
      <material
        name="">
        <color
          rgba="0.792156862745098 0.819607843137255 0.933333333333333 1" />
      </material>
    </visual>
    <collision>
      <origin
        xyz="0 0 0"
        rpy="0 0 0" />
      <geometry>
        <mesh
          filename="package://hivebot_trolley/meshes/compartment-1.STL" />
      </geometry>
    </collision>
  </link>
  <joint
    name="compartment-1-tobase"
    type="fixed">
    <origin
      xyz="-0.2 0.125 0"
      rpy="0 0 3.1416" />
    <parent
      link="base_link" />
    <child
      link="compartment-1" />
    <axis
      xyz="0 0 0" />
  </joint>
  <link
    name="door-1">
    <inertial>
      <origin
        xyz="0.295291950301883 0.10382999581969 1.11022302462516E-16"
        rpy="0 0 0" />
      <mass
        value="0.209666054570214" />
      <inertia
        ixx="0.000868657642586339"
        ixy="6.35564875691627E-06"
        ixz="1.32216549110476E-20"
        iyy="0.00608837938603179"
        iyz="-6.38662842229742E-19"
        izz="0.00695354992429537" />
    </inertial>
    <visual>
      <origin
        xyz="0 0 0"
        rpy="0 0 0" />
      <geometry>
        <mesh
          filename="package://hivebot_trolley/meshes/door-1.STL" />
      </geometry>
      <material
        name="">
        <color
          rgba="0.792156862745098 0.819607843137255 0.933333333333333 1" />
      </material>
    </visual>
    <collision>
      <origin
        xyz="0 0 0"
        rpy="0 0 0" />
      <geometry>
        <mesh
          filename="package://hivebot_trolley/meshes/door-1.STL" />
      </geometry>
    </collision>
  </link>
  <joint
    name="door-1-to-compartment"
    type="continuous">
    <origin
      xyz="-0.1 -0.115 0.01"
      rpy="1.568 -1.5708 0" />
    <parent
      link="compartment-1" />
    <child
      link="door-1" />
    <axis
      xyz="1 0 0" />
  </joint>
  <link
    name="compartment-2">
    <inertial>
      <origin
        xyz="0.000407919789025379 0.0298582952007898 0.273367873191963"
        rpy="0 0 0" />
      <mass
        value="5.66237181704939" />
      <inertia
        ixx="0.211234924589257"
        ixy="7.54303366478574E-17"
        ixz="2.25062829490829E-17"
        iyy="0.230542686133498"
        iyz="-0.0055394227160161"
        izz="0.0904301793877136" />
    </inertial>
    <visual>
      <origin
        xyz="0 0 0"
        rpy="0 0 0" />
      <geometry>
        <mesh
          filename="package://hivebot_trolley/meshes/compartment-2.STL" />
      </geometry>
      <material
        name="">
        <color
          rgba="0.792156862745098 0.819607843137255 0.933333333333333 1" />
      </material>
    </visual>
    <collision>
      <origin
        xyz="0 0 0"
        rpy="0 0 0" />
      <geometry>
        <mesh
          filename="package://hivebot_trolley/meshes/compartment-2.STL" />
      </geometry>
    </collision>
  </link>
  <joint
    name="compartment-2-to-base"
    type="fixed">
    <origin
      xyz="-0.2 -0.125 0"
      rpy="0 0 0" />
    <parent
      link="base_link" />
    <child
      link="compartment-2" />
    <axis
      xyz="0 0 0" />
  </joint>
  <link
    name="door-2">
    <inertial>
      <origin
        xyz="0.295291950301883 0.103829995819691 1.38777878078145E-16"
        rpy="0 0 0" />
      <mass
        value="0.209666054570215" />
      <inertia
        ixx="0.000868657642586341"
        ixy="6.35564875691666E-06"
        ixz="-7.80593800454041E-20"
        iyy="0.0060883793860318"
        iyz="2.43945488809238E-19"
        izz="0.00695354992429538" />
    </inertial>
    <visual>
      <origin
        xyz="0 0 0"
        rpy="0 0 0" />
      <geometry>
        <mesh
          filename="package://hivebot_trolley/meshes/door-2.STL" />
      </geometry>
      <material
        name="">
        <color
          rgba="0.792156862745098 0.819607843137255 0.933333333333333 1" />
      </material>
    </visual>
    <collision>
      <origin
        xyz="0 0 0"
        rpy="0 0 0" />
      <geometry>
        <mesh
          filename="package://hivebot_trolley/meshes/door-2.STL" />
      </geometry>
    </collision>
  </link>
  <joint
    name="door-2-to-compartment"
    type="continuous">
    <origin
      xyz="0.1 -0.115 0.01"
      rpy="1.5394 -1.5708 0" />
    <parent
      link="compartment-2" />
    <child
      link="door-2" />
    <axis
      xyz="1 0 0" />
  </joint>
</robot>