<?xml version="1.0" ?>
<!-- =================================================================================== -->
<!-- |    This document was autogenerated by xacro from /home/rishab/Developer/ros_workspaces/hivebot_ws/src/trolley_arm_description/urdf/trolley_arm.urdf.xacro | -->
<!-- |    EDITING THIS FILE BY HAND IS NOT RECOMMENDED                                 | -->
<!-- =================================================================================== -->
<robot name="trolley_arm_description">
    <link name="base_footprint" />
    <joint name="base_joint" type="fixed">
        <origin rpy="0 0 0" xyz="0 0 0.05" />
        <parent link="base_footprint" />
        <child link="base_link" />
    </joint>
    <link name="base_link">

        <inertial>
            <origin rpy="0 0 0" xyz="0.0235732763735559 -1.16156711654192E-16 -0.0393476182287232" />
            <mass value="63.3540430981409" />
            <inertia ixx="1.19803483723971" ixy="3.94354928014663E-16" ixz="0.00926065111324139" iyy="2.11869396240118" iyz="2.70482966665085E-18" izz="3.24789298834746" />
        </inertial>

        <visual>
            <origin rpy="0 0 0" xyz="0 0 0" />
            <geometry>
                <mesh filename="package://hivebot_trolley/meshes/base_link.STL" />
            </geometry>
            <material name="">
                <color rgba="0.898039215686275 0.917647058823529 0.929411764705882 1" />
            </material>
        </visual>
        <collision>
            <origin rpy="0 0 0" xyz="0 0 0" />
            <geometry>
                <mesh filename="package://hivebot_trolley/meshes/base_link.STL" />
            </geometry>
        </collision>
    </link>
    <joint name="compartment-2-to-base" type="fixed">
        <origin rpy="0 0 0" xyz="-0.2 -0.125 0" />
        <parent link="base_link" />
        <child link="compartment-2" />
        <axis xyz="0 0 0" />
    </joint>
    <link name="front_wheel_mount_plate_1">

        <inertial>
            <origin rpy="0 0 0" xyz="0 0 0.00372376098180309" />
            <mass value="0.0885122104446696" />
            <inertia ixx="4.96589186338358E-05" ixy="8.76460525250229E-21" ixz="4.57370748529084E-22" iyy="4.96589186338358E-05" iyz="-1.38813531491213E-23" izz="9.88794947001013E-05" />
        </inertial>

        <visual>
            <origin rpy="0 0 0" xyz="0 0 0" />
            <geometry>
                <mesh filename="package://hivebot_trolley/meshes/front_wheel_mount_plate_1.STL" />
            </geometry>
            <material name="">
                <color rgba="0.898039215686275 0.917647058823529 0.929411764705882 1" />
            </material>
        </visual>
        <collision>
            <origin rpy="0 0 0" xyz="0 0 0" />
            <geometry>
                <mesh filename="package://hivebot_trolley/meshes/front_wheel_mount_plate_1.STL" />
            </geometry>
        </collision>
    </link>
    <joint name="front_wheel_mount_plate_1_tobase" type="fixed">
        <origin rpy="0 0 0" xyz="0.28 -0.205 -0.086" />
        <parent link="base_link" />
        <child link="front_wheel_mount_plate_1" />
        <axis xyz="0 0 0" />
    </joint>
    <link name="front_wheel_holder_1">

        <inertial>
            <origin rpy="0 0 0" xyz="0 -5.55111512312578E-17 -0.0353498305391301" />
            <mass value="0.40765592096642" />
            <inertia ixx="0.000762776791330026" ixy="1.03138220220553E-05" ixz="6.91311896835273E-20" iyy="0.000501675770186767" iyz="-1.75192826322455E-19" izz="0.000528106575482838" />
        </inertial>

        <visual>
            <origin rpy="0 0 0" xyz="0 0 0" />
            <geometry>
                <mesh filename="package://hivebot_trolley/meshes/front_wheel_holder_1.STL" />
            </geometry>
            <material name="">
                <color rgba="0.898039215686275 0.917647058823529 0.929411764705882 1" />
            </material>
        </visual>
        <collision>
            <origin rpy="0 0 0" xyz="0 0 0" />
            <geometry>
                <mesh filename="package://hivebot_trolley/meshes/front_wheel_holder_1.STL" />
            </geometry>
        </collision>
    </link>
    <joint name="front_wheel_holder_1_toplate" type="fixed">
        <origin rpy="0 0 0" xyz="0 0 0" />
        <parent link="front_wheel_mount_plate_1" />
        <child link="front_wheel_holder_1" />
        <axis xyz="0 0 -1" />
    </joint>
    <link name="front_wheel_1">

        <inertial>
            <origin rpy="0 0 0" xyz="5.55111512312578E-17 8.32667268468867E-17 -5.55111512312578E-17" />
            <mass value="1.73558464244813" />
            <inertia ixx="0.00211027858785498" ixy="-5.2803822366633E-05" ixz="1.94419187005969E-19" iyy="0.00344704122644933" iyz="-2.97963645002492E-19" izz="0.00210819601428248" />
        </inertial>

        <visual>
            <origin rpy="0 0 0" xyz="0 0 0" />
            <geometry>
                <mesh filename="package://hivebot_trolley/meshes/front_wheel_1.STL" />
            </geometry>
            <material name="">
                <color rgba="0.898039215686275 0.917647058823529 0.929411764705882 1" />
            </material>
        </visual>
        <collision>
            <origin rpy="0 0 0" xyz="0 0 0" />
            <geometry>
                <mesh filename="package://hivebot_trolley/meshes/front_wheel_1.STL" />
            </geometry>
        </collision>
    </link>
    <joint name="front_wheel_1_to_holder" type="fixed">
        <origin rpy="0 0 0" xyz="0 0 -0.081" />
        <parent link="front_wheel_holder_1" />
        <child link="front_wheel_1" />
        <axis xyz="-0.0394091875345171 0.99922315622581 0" />
    </joint>
    <link name="front_wheel_mount_plate_2">

        <inertial>
            <origin rpy="0 0 0" xyz="0 -2.77555756156289E-17 0.00372376098180309" />
            <mass value="0.0885122104446697" />
            <inertia ixx="4.96589186338359E-05" ixy="1.33252491072572E-20" ixz="1.0447510163914E-22" iyy="4.96589186338359E-05" iyz="6.3556804032152E-22" izz="9.88794947001014E-05" />
        </inertial>

        <visual>
            <origin rpy="0 0 0" xyz="0 0 0" />
            <geometry>
                <mesh filename="package://hivebot_trolley/meshes/front_wheel_mount_plate_2.STL" />
            </geometry>
            <material name="">
                <color rgba="0.898039215686275 0.917647058823529 0.929411764705882 1" />
            </material>
        </visual>
        <collision>
            <origin rpy="0 0 0" xyz="0 0 0" />
            <geometry>
                <mesh filename="package://hivebot_trolley/meshes/front_wheel_mount_plate_2.STL" />
            </geometry>
        </collision>
    </link>
    <joint name="front_wheel_mount_plate_2_tobase" type="fixed">
        <origin rpy="0 0 0" xyz="0.28 0.205 -0.086" />
        <parent link="base_link" />
        <child link="front_wheel_mount_plate_2" />
        <axis xyz="0 0 0" />
    </joint>
    <link name="front_wheel_holder_2">

        <inertial>
            <origin rpy="0 0 0" xyz="-5.55111512312578E-17 -5.55111512312578E-17 -0.0353498305391302" />
            <mass value="0.40765592096642" />
            <inertia ixx="0.00076152629456158" ixy="2.07681767546495E-05" ixz="-6.15417341469107E-20" iyy="0.000502926266955213" iyz="3.73082590857221E-19" izz="0.000528106575482838" />
        </inertial>

        <visual>
            <origin rpy="0 0 0" xyz="0 0 0" />
            <geometry>
                <mesh filename="package://hivebot_trolley/meshes/front_wheel_holder_2.STL" />
            </geometry>
            <material name="">
                <color rgba="0.898039215686275 0.917647058823529 0.929411764705882 1" />
            </material>
        </visual>
        <collision>
            <origin rpy="0 0 0" xyz="0 0 0" />
            <geometry>
                <mesh filename="package://hivebot_trolley/meshes/front_wheel_holder_2.STL" />
            </geometry>
        </collision>
    </link>
    <joint name="front_wheel_holder_2_toplate" type="fixed">
        <origin rpy="0 0 0" xyz="0 0 0" />
        <parent link="front_wheel_mount_plate_2" />
        <child link="front_wheel_holder_2" />
        <axis xyz="0 0 -1" />
    </joint>
    <link name="front_wheel_2">

        <inertial>
            <origin rpy="0 0 0" xyz="5.55111512312578E-17 0 0" />
            <mass value="1.73558464244813" />
            <inertia ixx="0.00211668077407555" ixy="-0.000106327132064745" ixz="-2.97271341358694E-19" iyy="0.00344063904022875" iyz="-1.72056927832268E-21" izz="0.00210819601428248" />
        </inertial>

        <visual>
            <origin rpy="0 0 0" xyz="0 0 0" />
            <geometry>
                <mesh filename="package://hivebot_trolley/meshes/front_wheel_2.STL" />
            </geometry>
            <material name="">
                <color rgba="0.898039215686275 0.917647058823529 0.929411764705882 1" />
            </material>
        </visual>
        <collision>
            <origin rpy="0 0 0" xyz="0 0 0" />
            <geometry>
                <mesh filename="package://hivebot_trolley/meshes/front_wheel_2.STL" />
            </geometry>
        </collision>
    </link>
    <joint name="front_wheel_2_toholder" type="fixed">
        <origin rpy="0 0 0" xyz="0 0 -0.081" />
        <parent link="front_wheel_holder_2" />
        <child link="front_wheel_2" />
        <axis xyz="0.0795457683033873 -0.996831214772603 0" />
    </joint>
    <link name="back_wheel_holder_2">

        <inertial>
            <origin rpy="0 0 0" xyz="-2.77555756156289E-17 0.12370581952403 2.77555756156289E-17" />
            <mass value="3.69062219624929" />
            <inertia ixx="0.00912658772080383" ixy="8.63502453250557E-19" ixz="-5.57023878196132E-19" iyy="0.00672881943632791" iyz="-2.81940192519475E-19" izz="0.0103145877208038" />
        </inertial>

        <visual>
            <origin rpy="0 0 0" xyz="0 0 0" />
            <geometry>
                <mesh filename="package://hivebot_trolley/meshes/back_wheel_holder_2.STL" />
            </geometry>
            <material name="">
                <color rgba="0.898039215686275 0.917647058823529 0.929411764705882 1" />
            </material>
        </visual>
        <collision>
            <origin rpy="0 0 0" xyz="0 0 0" />
            <geometry>
                <mesh filename="package://hivebot_trolley/meshes/back_wheel_holder_2.STL" />
            </geometry>
        </collision>
    </link>
    <joint name="back_wheel_holder_2_tobase" type="fixed">
        <origin rpy="0 0 0" xyz="-0.2185 -0.25 -0.13" />
        <parent link="base_link" />
        <child link="back_wheel_holder_2" />
        <axis xyz="0 0 0" />
    </joint>
    <link name="back_wheel_2">

        <inertial>
            <origin rpy="0 0 0" xyz="-5.55111512312578E-17 0.0399999999999996 4.16333634234434E-16" />
            <mass value="7.27255451520401" />
            <inertia ixx="0.0256368152469609" ixy="-3.1162102280413E-18" ixz="-1.17965325757309E-22" iyy="0.0435162390110376" iyz="2.68645908030935E-18" izz="0.0256368152469609" />
        </inertial>

        <visual>
            <origin rpy="0 0 0" xyz="0 0 0" />
            <geometry>
                <mesh filename="package://hivebot_trolley/meshes/back_wheel_2.STL" />
            </geometry>
            <material name="">
                <color rgba="0.898039215686275 0.917647058823529 0.929411764705882 1" />
            </material>
        </visual>
        <collision>
            <origin rpy="0 0 0" xyz="0 0 0" />
            <geometry>
                <mesh filename="package://hivebot_trolley/meshes/back_wheel_2.STL" />
            </geometry>
        </collision>
    </link>
    <joint name="back_wheel_2_toholder" type="fixed">
        <origin rpy="0 0 0" xyz="0 0 0" />
        <parent link="back_wheel_holder_2" />
        <child link="back_wheel_2" />
        <axis xyz="0 1 0" />
    </joint>
    <link name="back_wheel_holder_1">

        <inertial>
            <origin rpy="0 0 0" xyz="2.77555756156289E-17 -0.12370581952403 -2.77555756156289E-17" />
            <mass value="3.69062219624929" />
            <inertia ixx="0.00912658772080382" ixy="-5.58383894595012E-19" ixz="8.67342168411457E-19" iyy="0.00672881943632791" iyz="6.69411038953511E-20" izz="0.0103145877208038" />
        </inertial>

        <visual>
            <origin rpy="0 0 0" xyz="0 0 0" />
            <geometry>
                <mesh filename="package://hivebot_trolley/meshes/back_wheel_holder_1.STL" />
            </geometry>
            <material name="">
                <color rgba="0.898039215686275 0.917647058823529 0.929411764705882 1" />
            </material>
        </visual>
        <collision>
            <origin rpy="0 0 0" xyz="0 0 0" />
            <geometry>
                <mesh filename="package://hivebot_trolley/meshes/back_wheel_holder_1.STL" />
            </geometry>
        </collision>
    </link>
    <joint name="back_wheel_holder_1_tobase" type="fixed">
        <origin rpy="0 0 0" xyz="-0.2185 0.25 -0.13" />
        <parent link="base_link" />
        <child link="back_wheel_holder_1" />
        <axis xyz="0 0 0" />
    </joint>
    <link name="back_wheel_1">

        <inertial>
            <origin rpy="0 0 0" xyz="-5.55111512312578E-17 -0.04 0" />
            <mass value="7.27255451520401" />
            <inertia ixx="0.0256368152469609" ixy="-2.25459743055601E-18" ixz="1.57683124065269E-19" iyy="0.0435162390110376" iyz="4.84744605090424E-18" izz="0.0256368152469609" />
        </inertial>

        <visual>
            <origin rpy="0 0 0" xyz="0 0 0" />
            <geometry>
                <mesh filename="package://hivebot_trolley/meshes/back_wheel_1.STL" />
            </geometry>
            <material name="">
                <color rgba="0.898039215686275 0.917647058823529 0.929411764705882 1" />
            </material>
        </visual>
        <collision>
            <origin rpy="0 0 0" xyz="0 0 0" />
            <geometry>
                <mesh filename="package://hivebot_trolley/meshes/back_wheel_1.STL" />
            </geometry>
        </collision>
    </link>
    <joint name="back_wheel_1_toholder" type="continuous">
        <origin rpy="0 0 0" xyz="0 0 0" />
        <parent link="back_wheel_holder_1" />
        <child link="back_wheel_1" />
        <axis xyz="0 -1 0" />
        <dynamics damping="0.7" friction="10"/>
    </joint>
    <link name="guiding_frame-2">

        <inertial>
            <origin rpy="0 0 0" xyz="5.55111512312578E-17 -1.36557830061531E-16 -0.52082343378767" />
            <mass value="15.546168" />
            <inertia ixx="1.04667928751446" ixy="-1.21627735877006E-18" ixz="9.73209658663459E-17" iyy="0.99672874017046" iyz="1.5679887871354E-16" izz="0.076308340032" />
        </inertial>

        <visual>
            <origin rpy="0 0 0" xyz="0 0 0" />
            <geometry>
                <mesh filename="package://hivebot_trolley/meshes/guiding_frame-2.STL" />
            </geometry>
            <material name="">
                <color rgba="0.898039215686275 0.917647058823529 0.929411764705882 1" />
            </material>
        </visual>
        <collision>
            <origin rpy="0 0 0" xyz="0 0 0" />
            <geometry>
                <mesh filename="package://hivebot_trolley/meshes/guiding_frame-2.STL" />
            </geometry>
        </collision>
    </link>
    <joint name="guiding-frame-2-tobase" type="fixed">
        <origin rpy="0 0 0" xyz="0.275 0 0.81" />
        <parent link="base_link" />
        <child link="guiding_frame-2" />
        <axis xyz="0 0 0" />
    </joint>
    <link name="mount-box">

        <inertial>
            <origin rpy="0 0 0" xyz="-3.33066907387547E-16 -5.43166688588743E-17 8.31973379078477E-13" />
            <mass value="3.88364559868246" />
            <inertia ixx="0.00932475709657866" ixy="-3.73105112956337E-19" ixz="-7.61186554870903E-19" iyy="0.00785069349852472" iyz="3.77869461474261E-19" izz="0.00784612520652471" />
        </inertial>

        <visual>
            <origin rpy="0 0 0" xyz="0 0 0" />
            <geometry>
                <mesh filename="package://hivebot_trolley/meshes/mount-box.STL" />
            </geometry>
            <material name="">
                <color rgba="0.898039215686275 0.917647058823529 0.929411764705882 1" />
            </material>
        </visual>
        <collision>
            <origin rpy="0 0 0" xyz="0 0 0" />
            <geometry>
                <mesh filename="package://hivebot_trolley/meshes/mount-box.STL" />
            </geometry>
        </collision>
    </link>
    <joint name="mount_box_to_frame" type="prismatic">
        <origin rpy="0 0 0" xyz="0 0 -0.57843375382" />
        <parent link="guiding_frame-2" />
        <child link="mount-box" />
        <axis xyz="0 0 1" />
        <limit effort="100" lower="0" upper="0.48" velocity="1" />
        <dynamics damping="0.7" friction="10"/>
    </joint>
    <link name="surrounding-frame">

        <inertial>
            <origin rpy="0 0 0" xyz="0.0846729181735194 0.000767773564878785 0.214525253910696" />
            <mass value="82.7476434299921" />
            <inertia ixx="3.78200016445154" ixy="-0.00222325591596084" ixz="-0.0201090148476572" iyy="3.39224065150316" iyz="-0.00236895559099694" izz="1.86426383436205" />
        </inertial>

        <visual>
            <origin rpy="0 0 0" xyz="0 0 0" />
            <geometry>
                <mesh filename="package://hivebot_trolley/meshes/surrounding-frame.STL" />
            </geometry>
            <material name="">
                <color rgba="0.898039215686275 0.917647058823529 0.929411764705882 1" />
            </material>
        </visual>
        <collision>
            <origin rpy="0 0 0" xyz="0 0 0" />
            <geometry>
                <mesh filename="package://hivebot_trolley/meshes/surrounding-frame.STL" />
            </geometry>
        </collision>
    </link>
    <joint name="surrounding-frame-to-base" type="fixed">
        <origin rpy="0 0 0" xyz="0.0749999999999998 0 0.16" />
        <parent link="base_link" />
        <child link="surrounding-frame" />
        <axis xyz="0 0 0" />
    </joint>
    <link name="cover-door">

        <inertial>
            <origin rpy="0 0 0" xyz="-0.150040997767576 -0.137889670402826 0.000346830907110185" />
            <mass value="2.05892920065877" />
            <inertia ixx="0.0140981800413022" ixy="-8.61535975977684E-06" ixz="2.2775979768361E-06" iyy="0.0153884352208601" iyz="4.71234485426862E-05" izz="0.0293377145153787" />
        </inertial>

        <visual>
            <origin rpy="0 0 0" xyz="0 0 0" />
            <geometry>
                <mesh filename="package://hivebot_trolley/meshes/cover-door.STL" />
            </geometry>
            <material name="">
                <color rgba="1 1 1 0.3" />
            </material>
        </visual>
        <collision>
            <origin rpy="0 0 0" xyz="0 0 0" />
            <geometry>
                <mesh filename="package://hivebot_trolley/meshes/cover-door.STL" />
            </geometry>
        </collision>
    </link>
    <joint name="cover-door-to-frame" type="fixed">
        <origin rpy="0 0 0" xyz="0.0899999999999999 0.118551612567476 0.64" />
        <parent link="surrounding-frame" />
        <child link="cover-door" />
        <axis xyz="-1 0 0" />
    </joint>
    <link name="tablet">

        <inertial>
            <origin rpy="0 0 0" xyz="-0.00212538959044117 -1.36883635898138E-05 0.00206874607906293" />
            <mass value="0.886766298135032" />
            <inertia ixx="0.00278972059920181" ixy="1.27724561345949E-07" ixz="-0.000432117490733407" iyy="0.000869274675297478" iyz="1.28403830937449E-07" izz="0.00278929527162149" />
        </inertial>

        <visual>
            <origin rpy="0 0 0" xyz="0 0 0" />
            <geometry>
                <mesh filename="package://hivebot_trolley/meshes/tablet.STL" />
            </geometry>
            <material name="">
                <color rgba="0.529411764705882 0.549019607843137 0.549019607843137 1" />
            </material>
        </visual>
        <collision>
            <origin rpy="0 0 0" xyz="0 0 0" />
            <geometry>
                <mesh filename="package://hivebot_trolley/meshes/tablet.STL" />
            </geometry>
        </collision>
    </link>
    <joint name="tablet-to-frame" type="fixed">
        <origin rpy="0 0 0" xyz="-0.323639610306789 0.001 0.579289321881345" />
        <parent link="surrounding-frame" />
        <child link="tablet" />
        <axis xyz="0 0 0" />
    </joint>
    <link name="handle">

        <inertial>
            <origin rpy="0 0 0" xyz="-0.0683128872678795 0.2 0" />
            <mass value="1.03600411126002" />
            <inertia ixx="0.0211986755913615" ixy="-3.76213226232454E-18" ixz="5.2805489928396E-20" iyy="0.000609084661143678" iyz="-5.58622665846924E-19" izz="0.0216912097899884" />
        </inertial>

        <visual>
            <origin rpy="0 0 0" xyz="0 0 0" />
            <geometry>
                <mesh filename="package://hivebot_trolley/meshes/handle.STL" />
            </geometry>
            <material name="">
                <color rgba="0.898039215686275 0.917647058823529 0.929411764705882 1" />
            </material>
        </visual>
        <collision>
            <origin rpy="0 0 0" xyz="0 0 0" />
            <geometry>
                <mesh filename="package://hivebot_trolley/meshes/handle.STL" />
            </geometry>
        </collision>
    </link>
    <joint name="handle-to-frame" type="fixed">
        <origin rpy="0 0 0" xyz="-0.4 -0.2 0.47" />
        <parent link="surrounding-frame" />
        <child link="handle" />
        <axis xyz="0 0 0" />
    </joint>
    <link name="tools">

        <inertial>
            <origin rpy="0 0 0" xyz="0.0135685512178612 -0.226707429071848 0.000429751102776738" />
            <mass value="1.10101723384343" />
            <inertia ixx="0.00181676017997894" ixy="-5.7000778196603E-19" ixz="2.91688343620181E-05" iyy="0.00170795242556321" iyz="-4.21950089664413E-19" izz="0.00133528189029824" />
        </inertial>

        <visual>
            <origin rpy="0 0 0" xyz="0 0 0" />
            <geometry>
                <mesh filename="package://hivebot_trolley/meshes/tools.STL" />
            </geometry>
            <material name="">
                <color rgba="0.898039215686275 0.917647058823529 0.929411764705882 1" />
            </material>
        </visual>
        <collision>
            <origin rpy="0 0 0" xyz="0 0 0" />
            <geometry>
                <mesh filename="package://hivebot_trolley/meshes/tools.STL" />
            </geometry>
        </collision>
    </link>
    <joint name="tools-to-frame" type="fixed">
        <origin rpy="0 0 0" xyz="0.243049636115999 0.226707429071858 0.0599999999999998" />
        <parent link="surrounding-frame" />
        <child link="tools" />
        <axis xyz="0 0 0" />
    </joint>
    <link name="compartment-1">

        <inertial>
            <origin rpy="0 0 0" xyz="0.0159462607609362 -0.00910725247573026 0.274676056153122" />
            <mass value="1.05739476651221" />
            <inertia ixx="0.033888709501066" ixy="1.08388147884056E-17" ixz="-1.95856102547443E-19" iyy="0.0369783137022633" iyz="0.000886251680853717" izz="0.0144797683018268" />
        </inertial>

        <visual>
            <origin rpy="0 0 0" xyz="0 0 0" />
            <geometry>
                <mesh filename="package://hivebot_trolley/meshes/compartment-1.STL" />
            </geometry>
            <material name="">
                <color rgba="1 1 1 1" />
            </material>
        </visual>
        <collision>
            <origin rpy="0 0 0" xyz="0 0 0" />
            <geometry>
                <mesh filename="package://hivebot_trolley/meshes/compartment-1.STL" />
            </geometry>
        </collision>
    </link>
    <joint name="compartment-1-tobase" type="fixed">
        <origin rpy="0 0 0" xyz="-0.2 0.125 0" />
        <parent link="base_link" />
        <child link="compartment-1" />
        <axis xyz="0 0 0" />
    </joint>
    <link name="door-1">

        <inertial>
            <origin rpy="0 0 0" xyz="-0.103829601822913 0.000286037081769358 0.295291950301883" />
            <mass value="0.209666054570214" />
            <inertia ixx="0.00608838595202948" ixy="2.38341449388362E-06" ixz="-6.35562463955881E-06" iyy="0.00695354335829767" iyz="1.75089212787349E-08" izz="0.000868657642586339" />
        </inertial>

        <visual>
            <origin rpy="0 0 0" xyz="0 0 0" />
            <geometry>
                <mesh filename="package://hivebot_trolley/meshes/door-1.STL" />
            </geometry>
            <material name="">
                <color rgba="1 1 1 1" />
            </material>
        </visual>
        <collision>
            <origin rpy="0 0 0" xyz="0 0 0" />
            <geometry>
                <mesh filename="package://hivebot_trolley/meshes/door-1.STL" />
            </geometry>
        </collision>
    </link>
    <joint name="door-1-to-compartment" type="fixed">
        <origin rpy="0 0 0" xyz="0.0999999999999994 0.115 0.00999999999999993" />
        <parent link="compartment-1" />
        <child link="door-1" />
        <axis xyz="0 0 1" />
    </joint>
    <link name="compartment-2">

        <inertial>
            <origin rpy="0 0 0" xyz="0.0159462607609365 0.00910725247573027 0.274676056153122" />
            <mass value="1.05739476651221" />
            <inertia ixx="0.033888709501066" ixy="1.20681831383722E-17" ixz="3.61843005233635E-18" iyy="0.0369783137022634" iyz="-0.000886251680853721" izz="0.0144797683018268" />
        </inertial>

        <visual>
            <origin rpy="0 0 0" xyz="0 0 0" />
            <geometry>
                <mesh filename="package://hivebot_trolley/meshes/compartment-2.STL" />
            </geometry>
            <material name="">
                <color rgba="1 1 1 1" />
            </material>
        </visual>
        <collision>
            <origin rpy="0 0 0" xyz="0 0 0" />
            <geometry>
                <mesh filename="package://hivebot_trolley/meshes/compartment-2.STL" />
            </geometry>
        </collision>
    </link>
    <link name="door-2">

        <inertial>
            <origin rpy="0 0 0" xyz="-0.103778785036784 -0.00326064536650364 0.295291950301883" />
            <mass value="0.209666054570215" />
            <inertia ixx="0.00608923261026625" ixy="-2.71561499219606E-05" ixz="-6.35251403899478E-06" iyy="0.00695269670006093" iyz="-1.99590845658357E-07" izz="0.000868657642586341" />
        </inertial>

        <visual>
            <origin rpy="0 0 0" xyz="0 0 0" />
            <geometry>
                <mesh filename="package://hivebot_trolley/meshes/door-2.STL" />
            </geometry>
            <material name="">
                <color rgba="1 1 1 1" />
            </material>
        </visual>
        <collision>
            <origin rpy="0 0 0" xyz="0 0 0" />
            <geometry>
                <mesh filename="package://hivebot_trolley/meshes/door-2.STL" />
            </geometry>
        </collision>
    </link>
    <joint name="door-2-to-compartment" type="fixed">
        <origin rpy="0 0 0" xyz="0.1 -0.115 0.00999999999999982" />
        <parent link="compartment-2" />
        <child link="door-2" />
        <axis xyz="0 0 1" />
    </joint>
    <link name="arm_base">

        <inertial>
            <origin rpy="0 0 0" xyz="-0.00314201374155656 -0.000316576969441296 0.0310618347596631" />
            <mass value="0.92353" />
            <inertia ixx="0.00084401" ixy="-7.3631E-06" ixz="1.4091E-06" iyy="0.00083129" iyz="-4.0382E-06" izz="0.0010931" />
        </inertial>

        <visual>
            <origin rpy="0 0 0" xyz="0 0 0" />
            <geometry>
                <mesh filename="package://mycobot_320/urdf/320_urdf/meshes/arm_base.STL" />
            </geometry>
            <material name="">
                <color rgba="0.752941176470588 0.752941176470588 0.752941176470588 1" />
            </material>
        </visual>
        <collision>
            <origin rpy="0 0 0" xyz="0 0 0" />
            <geometry>
                <mesh filename="package://mycobot_320/urdf/320_urdf/meshes/arm_base.STL" />
            </geometry>
        </collision>
    </link>
    <link name="j1">

        <inertial>
            <origin rpy="0 0 0" xyz="-4.65008859791595E-06 -0.00713845775566615 0.039058845834672" />
            <mass value="0.3331" />
            <inertia ixx="0.00029036" ixy="5.13E-08" ixz="-1.5737E-07" iyy="0.0002951" iyz="8.4643E-05" izz="0.00013646" />
        </inertial>

        <visual>
            <origin rpy="0 0 0" xyz="0 0 0" />
            <geometry>
                <mesh filename="package://mycobot_320/urdf/320_urdf/meshes/j1.STL" />
            </geometry>
            <material name="">
                <color rgba="0.752941176470588 0.752941176470588 0.752941176470588 1" />
            </material>
        </visual>
        <collision>
            <origin rpy="0 0 0" xyz="0 0 0" />
            <geometry>
                <mesh filename="package://mycobot_320/urdf/320_urdf/meshes/j1.STL" />
            </geometry>
        </collision>
    </link>
    <joint name="j1_to_base" type="revolute">
        <safety_controller k_position="100.0" k_velocity="40.0" soft_lower_limit="-2.8973" soft_upper_limit="2.8973"/>
        <origin rpy="0 0 1.5423" xyz="0 0 0.072677" />
        <parent link="arm_base" />
        <child link="j1" />
        <axis xyz="0 0 1" />
        <limit effort="87" lower="-2.97" upper="2.97" velocity="2.1750" />
        <dynamics damping="0.7" friction="10"/>
    </joint>
    <link name="j2">

        <inertial>
            <origin rpy="0 0 0" xyz="-0.0513897959483668 1.03416109062133E-07 0.0428557705148588" />
            <mass value="0.29389" />
            <inertia ixx="8.6708E-05" ixy="-4.9801E-08" ixz="-1.5666E-05" iyy="0.00070218" iyz="3.0907E-08" izz="0.0007426" />
        </inertial>

        <visual>
            <origin rpy="0 0 0" xyz="0 0 0" />
            <geometry>
                <mesh filename="package://mycobot_320/urdf/320_urdf/meshes/j2.STL" />
            </geometry>
            <material name="">
                <color rgba="0.752941176470588 0.752941176470588 0.752941176470588 1" />
            </material>
        </visual>
        <collision>
            <origin rpy="0 0 0" xyz="0 0 0" />
            <geometry>
                <mesh filename="package://mycobot_320/urdf/320_urdf/meshes/j2.STL" />
            </geometry>
        </collision>
    </link>
    <joint name="j2_to_j1" type="revolute">
        <safety_controller k_position="100.0" k_velocity="40.0" soft_lower_limit="-1.7628" soft_upper_limit="1.7628"/>
        <origin rpy="1.5708 1.5527 0" xyz="0 -0.0035666 0.06053" />
        <parent link="j1" />
        <child link="j2" />
        <axis xyz="0 0 1" />
        <limit effort="10" lower="-2.79" upper="2.79" velocity="3.14" />
        <dynamics damping="0.7" friction="10"/>
    </joint>
    <link name="j3">

        <inertial>
            <origin rpy="0 0 0" xyz="-0.0437220859914132 -1.2774481847333E-06 0.00135653065468257" />
            <mass value="0.41605" />
            <inertia ixx="0.00010682" ixy="-3.791E-08" ixz="-3.1585E-05" iyy="0.00075981" iyz="-1.9856E-08" izz="0.0007926" />
        </inertial>

        <visual>
            <origin rpy="0 0 0" xyz="0 0 0" />
            <geometry>
                <mesh filename="package://mycobot_320/urdf/320_urdf/meshes/j3.STL" />
            </geometry>
            <material name="">
                <color rgba="0.752941176470588 0.752941176470588 0.752941176470588 1" />
            </material>
        </visual>
        <collision>
            <origin rpy="0 0 0" xyz="0 0 0" />
            <geometry>
                <mesh filename="package://mycobot_320/urdf/320_urdf/meshes/j3.STL" />
            </geometry>
        </collision>
    </link>
    <joint name="j3_to_j2" type="revolute">
        <origin rpy="0 0 -0.43585" xyz="-0.1102 0 0" />
        <parent link="j2" />
        <child link="j3" />
        <axis xyz="0 0 1" />
        <limit effort="10" lower="-2.79" upper="2.79" velocity="1" />
        <dynamics damping="0.7" friction="10"/>
    </joint>
    <link name="j4">

        <inertial>
            <origin rpy="0 0 0" xyz="-1.40520224535812E-05 -0.0076816570577589 0.0230103540086662" />
            <mass value="0.18777" />
            <inertia ixx="7.2775E-05" ixy="-9.7964E-10" ixz="1.8973E-08" iyy="6.1005E-05" iyz="2.5828E-05" izz="6.0395E-05" />
        </inertial>

        <visual>
            <origin rpy="0 0 0" xyz="0 0 0" />
            <geometry>
                <mesh filename="package://mycobot_320/urdf/320_urdf/meshes/j4.STL" />
            </geometry>
            <material name="">
                <color rgba="0.752941176470588 0.752941176470588 0.752941176470588 1" />
            </material>
        </visual>
        <collision>
            <origin rpy="0 0 0" xyz="0 0 0" />
            <geometry>
                <mesh filename="package://mycobot_320/urdf/320_urdf/meshes/j4.STL" />
            </geometry>
        </collision>
    </link>
    <joint name="j4_to_j3" type="revolute">
        <origin rpy="0 0 0.56721" xyz="-0.096 0 0.027014" />
        <parent link="j3" />
        <child link="j4" />
        <axis xyz="0 0 1" />
        <limit effort="10" lower="-2.79" upper="2.79" velocity="1" />
        <dynamics damping="0.7" friction="10"/>
    </joint>
    <link name="j5">

        <inertial>
            <origin rpy="0 0 0" xyz="0.000112529211153511 0.00287540778498707 0.0396485032237697" />
            <mass value="0.22519" />
            <inertia ixx="0.00010227" ixy="-2.212E-07" ixz="-8.7613E-08" iyy="0.00010156" iyz="-2.3391E-05" izz="6.5009E-05" />
        </inertial>

        <visual>
            <origin rpy="0 0 0" xyz="0 0 0" />
            <geometry>
                <mesh filename="package://mycobot_320/urdf/320_urdf/meshes/j5.STL" />
            </geometry>
            <material name="">
                <color rgba="0.752941176470588 0.752941176470588 0.752941176470588 1" />
            </material>
        </visual>
        <collision>
            <origin rpy="0 0 0" xyz="0 0 0" />
            <geometry>
                <mesh filename="package://mycobot_320/urdf/320_urdf/meshes/j5.STL" />
            </geometry>
        </collision>
    </link>
    <joint name="j5_to_j4" type="revolute">
        <origin rpy="1.5708 -0.64832 0" xyz="0 -0.024124 0.033515" />
        <parent link="j4" />
        <child link="j5" />
        <axis xyz="0 0 1" />
        <limit effort="10" lower="-2.97" upper="2.97" velocity="1" />
        <dynamics damping="0.7" friction="10"/>
    </joint>
    <link name="j6">

        <inertial>
            <origin rpy="0 0 0" xyz="-1.18357394707225E-06 -3.05824490363232E-06 0.0305489098542017" />
            <mass value="0.060102" />
            <inertia ixx="6.5539E-06" ixy="5.8245E-13" ixz="4.1933E-10" iyy="6.5568E-06" iyz="-1.023E-09" izz="1.0571E-05" />
        </inertial>

        <visual>
            <origin rpy="0 0 0" xyz="0 0 0" />
            <geometry>
                <mesh filename="package://mycobot_320/urdf/320_urdf/meshes/j6.STL" />
            </geometry>
            <material name="">
                <color rgba="0.792156862745098 0.819607843137255 0.933333333333333 1" />
            </material>
        </visual>
        <collision>
            <origin rpy="0 0 0" xyz="0 0 0" />
            <geometry>
                <mesh filename="package://mycobot_320/urdf/320_urdf/meshes/j6.STL" />
            </geometry>
        </collision>
    </link>
    <joint name="j6_to_j5" type="revolute">
        <origin rpy="-1.5708 0.0010726 0" xyz="0 0.0096091 0.051625" />
        <parent link="j5" />
        <child link="j6" />
        <axis xyz="0 0 1" />
        <limit effort="10" lower="-3.05" upper="3.05" velocity="1" />
        <dynamics damping="0.7" friction="10"/>
    </joint>
    <joint name="world_joint" type="fixed">
        <parent link="mount-box" />
        <child link="arm_base" />
        <origin rpy="0 1.5707 0" xyz="0.05 0 0" />
    </joint>

    <!-- <transmission name="trans_front_wheel_1_to_holder">
        <type>transmission_interface/SimpleTransmission</type>
        <joint name="front_wheel_1_to_holder">
            <hardwareInterface>hardware_interface/EffortJointInterface</hardwareInterface>
        </joint>
        <actuator name="front_wheel_1_to_holder_motor">
            <hardwareInterface>hardware_interface/EffortJointInterface</hardwareInterface>
            <mechanicalReduction>1</mechanicalReduction>
        </actuator>
    </transmission>
    <transmission name="trans_front_wheel_holder_2_toplate">
        <type>transmission_interface/SimpleTransmission</type>
        <joint name="front_wheel_holder_2_toplate">
            <hardwareInterface>hardware_interface/EffortJointInterface</hardwareInterface>
        </joint>
        <actuator name="front_wheel_holder_2_toplate_motor">
            <hardwareInterface>hardware_interface/EffortJointInterface</hardwareInterface>
            <mechanicalReduction>1</mechanicalReduction>
        </actuator>
    </transmission>
    <transmission name="trans_front_wheel_2_toholder">
        <type>transmission_interface/SimpleTransmission</type>
        <joint name="front_wheel_2_toholder">
            <hardwareInterface>hardware_interface/EffortJointInterface</hardwareInterface>
        </joint>
        <actuator name="front_wheel_2_toholder_motor">
            <hardwareInterface>hardware_interface/EffortJointInterface</hardwareInterface>
            <mechanicalReduction>1</mechanicalReduction>
        </actuator>
    </transmission>
    <transmission name="trans_back_wheel_2_toholder">
        <type>transmission_interface/SimpleTransmission</type>
        <joint name="back_wheel_2_toholder">
            <hardwareInterface>hardware_interface/EffortJointInterface</hardwareInterface>
        </joint>
        <actuator name="back_wheel_2_toholder_motor">
            <hardwareInterface>hardware_interface/EffortJointInterface</hardwareInterface>
            <mechanicalReduction>1</mechanicalReduction>
        </actuator>
    </transmission>
    <transmission name="trans_back_wheel_1_toholder">
        <type>transmission_interface/SimpleTransmission</type>
        <joint name="back_wheel_1_toholder">
            <hardwareInterface>hardware_interface/EffortJointInterface</hardwareInterface>
        </joint>
        <actuator name="back_wheel_1_toholder_motor">
            <hardwareInterface>hardware_interface/EffortJointInterface</hardwareInterface>
            <mechanicalReduction>1</mechanicalReduction>
        </actuator>
    </transmission> -->
    <transmission name="trans_mount_box_to_frame">
        <type>transmission_interface/SimpleTransmission</type>
        <joint name="mount_box_to_frame">
            <hardwareInterface>hardware_interface/EffortJointInterface</hardwareInterface>
        </joint>
        <actuator name="mount_box_to_frame_motor">
            <hardwareInterface>hardware_interface/EffortJointInterface</hardwareInterface>
            <mechanicalReduction>1</mechanicalReduction>
        </actuator>
    </transmission>
    <transmission name="trans_j1_to_base">
        <type>transmission_interface/SimpleTransmission</type>
        <joint name="j1_to_base">
            <hardwareInterface>hardware_interface/EffortJointInterface</hardwareInterface>
        </joint>
        <actuator name="j1_to_base_motor">
            <hardwareInterface>hardware_interface/EffortJointInterface</hardwareInterface>
            <mechanicalReduction>1</mechanicalReduction>
        </actuator>
    </transmission>
    <transmission name="trans_j2_to_j1">
        <type>transmission_interface/SimpleTransmission</type>
        <joint name="j2_to_j1">
            <hardwareInterface>hardware_interface/EffortJointInterface</hardwareInterface>
        </joint>
        <actuator name="j2_to_j1_motor">
            <hardwareInterface>hardware_interface/EffortJointInterface</hardwareInterface>
            <mechanicalReduction>1</mechanicalReduction>
        </actuator>
    </transmission>
    <transmission name="trans_j3_to_j2">
        <type>transmission_interface/SimpleTransmission</type>
        <joint name="j3_to_j2">
            <hardwareInterface>hardware_interface/EffortJointInterface</hardwareInterface>
        </joint>
        <actuator name="j3_to_j2_motor">
            <hardwareInterface>hardware_interface/EffortJointInterface</hardwareInterface>
            <mechanicalReduction>1</mechanicalReduction>
        </actuator>
    </transmission>
    <transmission name="trans_j4_to_j3">
        <type>transmission_interface/SimpleTransmission</type>
        <joint name="j4_to_j3">
            <hardwareInterface>hardware_interface/EffortJointInterface</hardwareInterface>
        </joint>
        <actuator name="j4_to_j3_motor">
            <hardwareInterface>hardware_interface/EffortJointInterface</hardwareInterface>
            <mechanicalReduction>1</mechanicalReduction>
        </actuator>
    </transmission>
    <transmission name="trans_j5_to_j4">
        <type>transmission_interface/SimpleTransmission</type>
        <joint name="j5_to_j4">
            <hardwareInterface>hardware_interface/EffortJointInterface</hardwareInterface>
        </joint>
        <actuator name="j5_to_j4_motor">
            <hardwareInterface>hardware_interface/EffortJointInterface</hardwareInterface>
            <mechanicalReduction>1</mechanicalReduction>
        </actuator>
    </transmission>
    <transmission name="trans_j6_to_j5">
        <type>transmission_interface/SimpleTransmission</type>
        <joint name="j6_to_j5">
            <hardwareInterface>hardware_interface/EffortJointInterface</hardwareInterface>
        </joint>
        <actuator name="j6_to_j5_motor">
            <hardwareInterface>hardware_interface/EffortJointInterface</hardwareInterface>
            <mechanicalReduction>1</mechanicalReduction>
        </actuator>
    </transmission>
    <gazebo>
        <plugin name="gazebo_ros_control" filename="libgazebo_ros_control.so">
            <robotSimType>gazebo_ros_control/DefaultRobotHWSim</robotSimType>
        </plugin>
    </gazebo>
    <!-- <gazebo reference="j1_to_base">
        <kp>1000000.0</kp>
        <kd>100.0</kd>
        <mu1>30.0</mu1>
        <mu2>30.0</mu2>
        <dynamics damping="0.0" friction="0.0"/>
        <selfCollide>false</selfCollide>
        <turnGravityOff>false</turnGravityOff>
    </gazebo>
    <gazebo reference="mount_box_to_frame">
        <kp>1000000.0</kp>
        <kd>100.0</kd>
        <mu1>30.0</mu1>
        <mu2>30.0</mu2>
        <dynamics damping="0.0" friction="0.0"/>
        <selfCollide>false</selfCollide>
        <turnGravityOff>false</turnGravityOff>
    </gazebo>
    <gazebo reference="base_link">
        <dynamics damping="0.0" friction="0.0"/>
        <selfCollide>false</selfCollide>
        <turnGravityOff>false</turnGravityOff>
    </gazebo>
    <gazebo reference="j2_to_j1">
        <kp>1000000.0</kp>
        <kd>100.0</kd>
        <mu1>30.0</mu1>
        <mu2>30.0</mu2>
        <dynamics damping="0.0" friction="0.0"/>
        <selfCollide>false</selfCollide>
        <turnGravityOff>false</turnGravityOff>
    </gazebo>
    <gazebo reference="j2_to_j1">
        <kp>1000000.0</kp>
        <kd>100.0</kd>
        <mu1>30.0</mu1>
        <mu2>30.0</mu2>
        <dynamics damping="0.0" friction="0.0"/>
        <selfCollide>false</selfCollide>
        <turnGravityOff>false</turnGravityOff>
    </gazebo>
    <gazebo reference="j3_to_j2">
        <kp>1000000.0</kp>
        <kd>100.0</kd>
        <mu1>30.0</mu1>
        <mu2>30.0</mu2>
        <dynamics damping="0.0" friction="0.0"/>
        <selfCollide>false</selfCollide>
        <turnGravityOff>false</turnGravityOff>
    </gazebo>
    <gazebo reference="j4_to_j3">
        <kp>1000000.0</kp>
        <kd>100.0</kd>
        <mu1>30.0</mu1>
        <mu2>30.0</mu2>
        <dynamics damping="0.0" friction="0.0"/>
        <selfCollide>false</selfCollide>
        <turnGravityOff>false</turnGravityOff>
    </gazebo>
    <gazebo reference="j5_to_j4">
        <kp>1000000.0</kp>
        <kd>100.0</kd>
        <mu1>30.0</mu1>
        <mu2>30.0</mu2>
        <dynamics damping="0.0" friction="0.0"/>
        <selfCollide>false</selfCollide>
        <turnGravityOff>false</turnGravityOff>
    </gazebo>
    <gazebo reference="j6_to_j5">
        <kp>1000000.0</kp>
        <kd>100.0</kd>
        <mu1>30.0</mu1>
        <mu2>30.0</mu2>
        <dynamics damping="0.0" friction="0.0"/>
        <selfCollide>false</selfCollide>
        <turnGravityOff>false</turnGravityOff>
    </gazebo> -->
</robot>